Workbook

Sheet READ ME
A1: Please Make a Copy of this Google sheet from the File Menu (by selecting File > Make a Copy)
A3: ▶ | C3: All Inclusive Resort Ratings Welcome! I originally created this spreadsheet to help my family decide which resort was right for us. Once I realized how useful it was, I thought this tool could benefit other families and individuals alike with their travel plans. Hope it helps! To effectively use this spreadsheet, make a copy and then you can use the filters found on the RESORTS tab. The original link prompts you to make a copy, but if you've gotten here through other means, select File > Make a Copy from the Menu or click on the link provided below. Any requests for Editor Access will be denied. The original spreadsheet is updated often. I recommend getting a fresh copy if you haven't done so in a while. Click on the following link to make a new copy: | E3: ▶ | G3: About Average User Ratings These ratings are an average of Trip Advisor, Google, Costco and Expedia. Trip Advisor ratings are calculated based on the number of Excellent reviews, the number of Very Good reviews, etc. Ratings are periodically updated. Anything with a rating less than 85 is filtered out but feel free to turn that off if you want by clicking on checkbox above the Avg User Rating header on the RESORTS tab, or manually in the DATA tab). If Value is important to you, sort by the Value Ratio column (by clicking on the checkbox above the Value Ratio heading on the RESORTS tab, or manually from highest to lowest on the DATA tab). About Pricing Use the information provided to help you compare resorts. Prices are representative of what you might expect to pay for a week's stay in March 2025. Family Prices are for one week, two adults and two kids in March 2025 or as close to it as I could find in the lowest priced room with a refundable rate booked direct with the resort. Adult Only Prices are for one week, two people in March 2025 or as close to it as I could find in the lowest priced room with a refundable rate booked direct with the resort. Guaranteed Connecting Rooms Guaranteed connecting rooms means you can choose this at the time of booking. It's not a request based on availability. | I3: ▶ | K3: Acknowledgements I’d like to thank fellow reddit user @gothamfury who granted every item on my wish list and transformed the original version of this spreadsheet into what you see today. If you would like to show your appreciation for his hard work, please consider buying him a coffee below:
K10: buymeacoffee.com/gothamfury
K13: How to Contribute If you're interested in helping me keep this updated or, have any questions, corrections or suggestions, please let me know! You can reach me via my reddit profile page here:
C15: All Inclusive Resort Ratings (latest update)
C18: Quick Tips The filters on the RESORTS tab work best if you work from left to right, selecting only the filters you need. You can reset filters by selecting their default value (in blue) or for any of the multi-select dropdowns, pressing delete once while the dropdown is selected. If you delete the actual dropdown, use CTRL-Z or COMMAND-Z to undo. Some dropdowns have checkboxes below them that allow you to modify the filter to exclude or include the selected options. Most filter headers have tooltip hints that appear when you hover over them. The DATA sheet is also available if you prefer to filter and sort using the native filter feature Google Sheets offers. | K18: @TheRealGuncho
J22: North Star Ratings System Explanation
J23: Hotel Rankings: Northstar Travel’s 10-Tier Classification System

Sheet RESORTS
A1: START w/ STEPS 1 & 2, then WORK LEFT to RIGHT | D1: {=XLOOKUP(D4,ResortsDD!D2:D2006,ResortsDD!E2:E2006,,0)} -> ALL | K1: =IFERROR(__xludf.DUMMYFUNCTION("IF(ISBLANK(K4),,LET(selected,REGEXREPLACE(JOIN(""|"",SPLIT(K4,"", "",FALSE)),""\+"",""\\+""), selected))"),"") | L1: =IFERROR(__xludf.DUMMYFUNCTION("IF(ISBLANK(L4),,LET(selected,JOIN(""|"",SPLIT(L4,"", "",FALSE)), IF(L5, JOIN(""|"",FILTER(TOCOL(ResortsDD!L2:L2006,1),NOT(REGEXMATCH(TOCOL(ResortsDD!L2:L2006,1),selected)))), selected)))"),"") | M1: =IFERROR(__xludf.DUMMYFUNCTION("IF(ISBLANK(M4),,LET(selected,JOIN(""|"",SPLIT(M4,"", "",FALSE)), IF(M5, JOIN(""|"",FILTER(TOCOL(ResortsDD!M2:M2006,1),NOT(REGEXMATCH(TOCOL(ResortsDD!M2:M2006,1),selected)))), selected)))"),"") | N1: =IFERROR(__xludf.DUMMYFUNCTION("IF(ISBLANK(N4),,LET(selected,JOIN(""|"",SPLIT(N4,"", "",FALSE)), IF(N5, JOIN(""|"",FILTER(TOCOL(ResortsDD!N2:N2006,1),NOT(REGEXMATCH(TOCOL(ResortsDD!N2:N2006,1),selected)))), selected)))"),"") | O1: =IF(O4,O4,) | P1: {=XLOOKUP(P4,ResortsDD!O2:O2006,ResortsDD!P2:P2006,,0)} -> ALL | Q1: =IFERROR(__xludf.DUMMYFUNCTION("IF(ISBLANK(Q4),,JOIN(""|"",SPLIT(Q4,"", "",FALSE)))"),"") | R1: =IFERROR(__xludf.DUMMYFUNCTION("IF(ISBLANK(R4),,JOIN("".*"",SORT(TOCOL(SPLIT(R4,"", "",FALSE)))))"),"") | S1: =IFERROR(__xludf.DUMMYFUNCTION("IF(ISBLANK(S4),,JOIN("".*"",SORT(TOCOL(SPLIT(S4,"", "",FALSE)))))"),"") | T1: =IF(T4,T4,) | U1: =IFERROR(__xludf.DUMMYFUNCTION("IF(ISBLANK(U4),,""^""&JOIN(""$|^"",SPLIT(U4,"", "",FALSE))&""$"")"),"") | V1: =IF(V4,V4,) | W1: {=IF(ISBLANK(W4),,XLOOKUP(W4,ResortsDD!W2:W2006,ResortsDD!X2:X2006,,0))} -> ALL | X1: {=IF(ISBLANK(X4),,XLOOKUP(X4,ResortsDD!Y2:Y2006,ResortsDD!Z2:Z2006,,0))} -> ALL | Y1: {=IF(ISBLANK(Y4),,XLOOKUP(Y4,ResortsDD!AA2:AA2006,ResortsDD!AB2:AB2006,,0))} -> ALL
A2: Skip Any Filters. Hover Over Headings for More Info. | B2: ► | C2: STEP 1 | D2: STEP 2 | G2: FILTER BY RATINGS | L2: FILTER BY LOCATION* | Q2: FILTER BY HOTEL BRAND / STYLE* | S2: FILTER BY HOTEL FEATURES / ACCOMODATIONS*
A3: =IFERROR(__xludf.DUMMYFUNCTION("LET(filters,TEXTJOIN("", "",TRUE, IF(C4<>""ALL"",C4,), IF(D4<>""The Sky's the Limit!"",E5&"" ""&D4,), TEXTJOIN("", "",TRUE,IFNA(FILTER(G7:J7,G4:J4<>""ALL""),)), TEXTJOIN("", "",TRUE,IFNA(FILTER(K3:N3,K4:N4<>""""),)), IF(O4,""Direct Flight"",), IF(P4<>""AL"&"L"",""To/From Airport"",), TEXTJOIN("", "",TRUE,IFNA(FILTER(Q3:S3,Q4:S4<>""""),)), IF(T4,""Connecting Rooms"",), IF(U4<>"""",""Beds"",), IF(V4,""High Rise"",), TEXTJOIN("", "",TRUE,IFNA(FILTER(W3:Y3,W4:Y4<>""ALL""),))), IF(LEN(filters),""Filtering By: "" "&"& filters,""SELECT A FILTER >""))"),"SELECT A FILTER >") -> SELECT A FILTER > | C3: Select One | D3: Select Your Budget | G3: Select a Rating | K3: No Go | L3: Country | M3: Area | N3: Airport | O3: Direct | P3: Time | Q3: Hotel Brand | R3: Hotel Style | S3: Features | T3: Connecting Rooms? | U3: Beds | V3: High Rise | W3: # of Rooms | X3: Year Built | Y3: Year Renovated
C4: ALL | D4: The Sky's the Limit! | G4: ALL | H4: ALL | I4: ALL | J4: ALL | O4: FALSE | P4: ALL | T4: FALSE | V4: FALSE | W4: ALL | X4: ALL | Y4: ALL
D5: Currency: | E5: USD | K5: TRUE | L5: TRUE | M5: TRUE | N5: TRUE
B6: FALSE | F6: FALSE | K6: =IFERROR(__xludf.DUMMYFUNCTION("IF(ISBLANK(K4),,IF(K5,""Exclude ""&IF(COUNTA(SPLIT(K4,"",""))>1,""Options"",""Option""),))"),"") | L6: =IFERROR(__xludf.DUMMYFUNCTION("IF(ISBLANK(L4),,IF(L5,""Exclude "",""Include "") & IF(COUNTA(SPLIT(L4,"",""))>1,""Countries"",""Country""))"),"") | M6: =IFERROR(__xludf.DUMMYFUNCTION("IF(ISBLANK(M4),,IF(M5,""Exclude "",""Include "") & IF(COUNTA(SPLIT(M4,"",""))>1,""Areas"",""Area""))"),"") | N6: =IFERROR(__xludf.DUMMYFUNCTION("IF(ISBLANK(N4),,IF(N5,""Exclude "",""Include "") & IF(COUNTA(SPLIT(N4,"",""))>1,""Airports"",""Airport""))"),"")
A7: ="Resorts (" & COUNTIFS(A8:A2006,"<>", A8:A2006,"<>No Resorts Match Your Filter Criteria") & " Found)" -> Resorts (445 Found) | B7: Avg User Rating | C7: Family / Adults Only | D7: Direct USD 2025 | E7: Direct CAD 2025 | F7: Value Ratio | G7: AAA | H7: Northstar | I7: Hyatt | J7: Hotel Class | K7: No Go | L7: Country | M7: Area | N7: Airport | O7: Direct Flight | P7: To / From Airport | Q7: Hotel Brand | R7: Hotel Style | S7: Features | T7: Guaranteed Connecting Rooms | U7: Beds | V7: High Rise | W7: # of Rooms | X7: Year Built | Y7: Year Renovated | Z7: Floors
A8: =IFERROR(__xludf.DUMMYFUNCTION("LET(r,IFNA(FILTER({DATA!A2:F2006,DATA!R2:AK2006}, NOT(REGEXMATCH(DATA!V2:V2006,TEXTJOIN(""|"",TRUE,TOCOL(ResortsDD!A2:A2006,1)))), IF(RESORTS!B6,DATA!B2:B2006<9^9,DATA!B2:B2006>=85), REGEXMATCH(DATA!C2:C2006,IF(RESORTS!C4=""ALL"","".*"",RESORTS!C4)), IF(O"&"R(ISTEXT(RESORTS!D1),RESORTS!E5<>""USD""),DATA!D2:D2006<9^9,(DATA!D2:D2006<=RESORTS!D1)*NOT(ISBLANK(DATA!D2:D2006))), IF(OR(ISTEXT(RESORTS!D1),RESORTS!E5<>""CAD""),DATA!E2:E2006<9^9,(DATA!E2:E2006<=RESORTS!D1)*NOT(ISBLANK(DATA!E2:E2006))), IF(RESORTS!G4="&"""ALL"",NOT(ISBLANK(DATA!R2:R2006))+ISBLANK(DATA!R2:R2006),IF(RESORTS!G4=""Approved"",(DATA!R2:R2006>0)*NOT(ISBLANK(DATA!R2:R2006)),(DATA!R2:R2006>=RESORTS!G4)*(DATA!R2:R2006<>""Approved""))), IF(RESORTS!H4=""ALL"",NOT(ISBLANK(DATA!S2:S2006))+ISBLANK(DATA"&"!S2:S2006),DATA!S2:S2006>=RESORTS!H4), IF(RESORTS!I4=""ALL"",NOT(ISBLANK(DATA!T2:T2006))+ISBLANK(DATA!T2:T2006),DATA!T2:T2006>=RESORTS!I4), IF(RESORTS!J4=""ALL"",NOT(ISBLANK(DATA!U2:U2006))+ISBLANK(DATA!U2:U2006),DATA!U2:U2006>=RESORTS!J4), IF(ISBLANK(RES"&"ORTS!K4),REGEXMATCH(DATA!V2:V2006,"".*""),IF(RESORTS!K5,NOT(REGEXMATCH(DATA!V2:V2006,RESORTS!K1)),REGEXMATCH(DATA!V2:V2006,RESORTS!K1))), REGEXMATCH(DATA!W2:W2006,IF(ISBLANK(RESORTS!L4),"".*"",RESORTS!L1)), REGEXMATCH(DATA!X2:X2006,IF(ISBLANK(RESORTS!M4),"&""".*"",RESORTS!M1)), REGEXMATCH(DATA!Y2:Y2006,IF(ISBLANK(RESORTS!N4),"".*"",RESORTS!N1)), IF(RESORTS!O4,DATA!Z2:Z2006=TRUE,REGEXMATCH(TO_TEXT(DATA!Z2:Z2006),"".*"")), IF(RESORTS!P4=""ALL"",DATA!AA2:AA2006<9^9,(DATA!AA2:AA2006<=RESORTS!P1)*NOT(ISBLANK(DATA"&"!AA2:AA2006))), REGEXMATCH(DATA!AB2:AB2006,IF(ISBLANK(RESORTS!Q4),"".*"",RESORTS!Q1)), REGEXMATCH(DATA!AL2:AL2006,IF(ISBLANK(RESORTS!R4),"".*"",RESORTS!R1)), REGEXMATCH(DATA!AM2:AM2006,IF(ISBLANK(RESORTS!S4),"".*"",RESORTS!S1)), IF(RESORTS!T4,REGEXMATCH(D"&"ATA!AE2:AE2006,TEXTJOIN(""|"",TRUE,TOCOL(ResortsDD!B2:B2006,1))),REGEXMATCH(DATA!AE2:AE2006,"".*"")), REGEXMATCH(DATA!AF2:AF2006,IF(ISBLANK(RESORTS!U4),"".*"",RESORTS!U1)), IF(RESORTS!V4,DATA!AG2:AG2006=FALSE,REGEXMATCH(TO_TEXT(DATA!AG2:AG2006),"".*"")), "&"IF(RESORTS!W4=""ALL"",DATA!AH2:AH2006<9^9,(DATA!AH2:AH2006<=RESORTS!W1)*NOT(ISBLANK(DATA!AH2:AH2006))), IF(RESORTS!X4=""ALL"",DATA!AI2:AI2006<9^9,(DATA!AI2:AI2006>=YEAR(TODAY())-RESORTS!X1)*NOT(ISBLANK(DATA!AI2:AI2006))), IF(RESORTS!Y4=""ALL"",DATA!AJ2:AJ"&"2006<9^9,(DATA!AJ2:AJ2006>=YEAR(TODAY())-RESORTS!Y1)*NOT(ISBLANK(DATA!AJ2:AJ2006))) ),""na""), IF(r=""na"",""No Resorts Match Your Filter Criteria"", SORT(r,IF(RESORTS!F6,6,2),0,4,1)))"),"Coco Plum Island Resort") -> Coco Plum Island Resort | B8: =IFERROR(__xludf.DUMMYFUNCTION("""COMPUTED_VALUE"""),98.5) -> 98.5 | C8: =IFERROR(__xludf.DUMMYFUNCTION("""COMPUTED_VALUE"""),"Adults Only") -> Adults Only | D8: =IFERROR(__xludf.DUMMYFUNCTION("""COMPUTED_VALUE"""),5799.99) -> 5799.99 | E8: =IFERROR(__xludf.DUMMYFUNCTION("""COMPUTED_VALUE"""),8010.075609500998) -> 8010.0756 | F8: =IFERROR(__xludf.DUMMYFUNCTION("""COMPUTED_VALUE"""),3.19) -> 3.19 | L8: =IFERROR(__xludf.DUMMYFUNCTION("""COMPUTED_VALUE"""),"Belize") -> Belize | M8: =IFERROR(__xludf.DUMMYFUNCTION("""COMPUTED_VALUE"""),"Coco Plum Cay") -> Coco Plum Cay | N8: =IFERROR(__xludf.DUMMYFUNCTION("""COMPUTED_VALUE"""),"Philip S.W. Goldson") -> Philip S.W. Goldson | O8: =IFERROR(__xludf.DUMMYFUNCTION("""COMPUTED_VALUE"""),TRUE) -> TRUE | R8: =IFERROR(__xludf.DUMMYFUNCTION("""COMPUTED_VALUE"""),"Romantic, Great View") -> Romantic, Great View | S8: =IFERROR(__xludf.DUMMYFUNCTION("""COMPUTED_VALUE"""),"Beach, Wifi (Free), Diving, Fishing, Yoga Classes") -> Beach, Wifi (Free), Diving, Fishing, Yoga Classes | V8: =IFERROR(__xludf.DUMMYFUNCTION("""COMPUTED_VALUE"""),FALSE) -> FALSE
A9: =IFERROR(__xludf.DUMMYFUNCTION("""COMPUTED_VALUE"""),"The Aerial BVI (Non refundable)") -> The Aerial BVI (Non refundable) | B9: =IFERROR(__xludf.DUMMYFUNCTION("""COMPUTED_VALUE"""),98.5) -> 98.5 | C9: =IFERROR(__xludf.DUMMYFUNCTION("""COMPUTED_VALUE"""),"Family") -> Family | D9: =IFERROR(__xludf.DUMMYFUNCTION("""COMPUTED_VALUE"""),18917.5) -> 18917.5 | E9: =IFERROR(__xludf.DUMMYFUNCTION("""COMPUTED_VALUE"""),26126.011483249997) -> 26126.011 | F9: =IFERROR(__xludf.DUMMYFUNCTION("""COMPUTED_VALUE"""),0.98) -> 0.98 | K9: =IFERROR(__xludf.DUMMYFUNCTION("""COMPUTED_VALUE"""),"Max 3 per Room, Non Refundable") -> Max 3 per Room, Non Refundable | L9: =IFERROR(__xludf.DUMMYFUNCTION("""COMPUTED_VALUE"""),"British Virgin Islands") -> British Virgin Islands | M9: =IFERROR(__xludf.DUMMYFUNCTION("""COMPUTED_VALUE"""),"Buck Island") -> Buck Island | N9: =IFERROR(__xludf.DUMMYFUNCTION("""COMPUTED_VALUE"""),"Beef Island") -> Beef Island | O9: =IFERROR(__xludf.DUMMYFUNCTION("""COMPUTED_VALUE"""),FALSE) -> FALSE | P9: =IFERROR(__xludf.DUMMYFUNCTION("""COMPUTED_VALUE"""),0.008333333333333333) -> 0.0083333333 | S9: =IFERROR(__xludf.DUMMYFUNCTION("""COMPUTED_VALUE"""),"Beach, Heated Pool, Wifi (Free), Spa, Gym, Horseback Riding, Watersports Equipment Rentals, Hiking, Snorkelling, Yoga Classes") -> Beach, Heated Pool, Wifi (Free), Spa, Gym, Horseback Riding, Watersports Equipment Rentals, Hiking, Snorkelling, Yoga Classes | U9: =IFERROR(__xludf.DUMMYFUNCTION("""COMPUTED_VALUE"""),"1 King") -> 1 King | V9: =IFERROR(__xludf.DUMMYFUNCTION("""COMPUTED_VALUE"""),FALSE) -> FALSE
A10: =IFERROR(__xludf.DUMMYFUNCTION("""COMPUTED_VALUE"""),"The Beachfront By The Fives Hotels") -> The Beachfront By The Fives Hotels | B10: =IFERROR(__xludf.DUMMYFUNCTION("""COMPUTED_VALUE"""),98.0) -> 98 | C10: =IFERROR(__xludf.DUMMYFUNCTION("""COMPUTED_VALUE"""),"Adults Only") -> Adults Only | D10: =IFERROR(__xludf.DUMMYFUNCTION("""COMPUTED_VALUE"""),5114.0) -> 5114 | E10: =IFERROR(__xludf.DUMMYFUNCTION("""COMPUTED_VALUE"""),7062.689188599999) -> 7062.6892 | F10: =IFERROR(__xludf.DUMMYFUNCTION("""COMPUTED_VALUE"""),3.52) -> 3.52 | H10: =IFERROR(__xludf.DUMMYFUNCTION("""COMPUTED_VALUE"""),"NYR") -> NYR | J10: =IFERROR(__xludf.DUMMYFUNCTION("""COMPUTED_VALUE"""),2.0) -> 2 | L10: =IFERROR(__xludf.DUMMYFUNCTION("""COMPUTED_VALUE"""),"Mexico") -> Mexico | M10: =IFERROR(__xludf.DUMMYFUNCTION("""COMPUTED_VALUE"""),"Playa del Carmen") -> Playa del Carmen | N10: =IFERROR(__xludf.DUMMYFUNCTION("""COMPUTED_VALUE"""),"Cancun") -> Cancun | O10: =IFERROR(__xludf.DUMMYFUNCTION("""COMPUTED_VALUE"""),TRUE) -> TRUE | P10: =IFERROR(__xludf.DUMMYFUNCTION("""COMPUTED_VALUE"""),0.030555555555555555) -> 0.030555556 | Q10: =IFERROR(__xludf.DUMMYFUNCTION("""COMPUTED_VALUE"""),"The Fives Hotels") -> The Fives Hotels | R10: =IFERROR(__xludf.DUMMYFUNCTION("""COMPUTED_VALUE"""),"Boutique, Business") -> Boutique, Business | S10: =IFERROR(__xludf.DUMMYFUNCTION("""COMPUTED_VALUE"""),"Beach, Swim Out/Plunge Pool Rooms, Gym, Spa, Wifi (Free), Snorkelling, Room Service") -> Beach, Swim Out/Plunge Pool Rooms, Gym, Spa, Wifi (Free), Snorkelling, Room Service | V10: =IFERROR(__xludf.DUMMYFUNCTION("""COMPUTED_VALUE"""),FALSE) -> FALSE | W10: =IFERROR(__xludf.DUMMYFUNCTION("""COMPUTED_VALUE"""),50.0) -> 50 | X10: =IFERROR(__xludf.DUMMYFUNCTION("""COMPUTED_VALUE"""),2023.0) -> 2023 | Z10: =IFERROR(__xludf.DUMMYFUNCTION("""COMPUTED_VALUE"""),3.0) -> 3
A11: =IFERROR(__xludf.DUMMYFUNCTION("""COMPUTED_VALUE"""),"Guana Island") -> Guana Island | B11: =IFERROR(__xludf.DUMMYFUNCTION("""COMPUTED_VALUE"""),98.0) -> 98 | C11: =IFERROR(__xludf.DUMMYFUNCTION("""COMPUTED_VALUE"""),"Family") -> Family | D11: =IFERROR(__xludf.DUMMYFUNCTION("""COMPUTED_VALUE"""),24367.0) -> 24367 | E11: =IFERROR(__xludf.DUMMYFUNCTION("""COMPUTED_VALUE"""),33652.04291329999) -> 33652.043 | F11: =IFERROR(__xludf.DUMMYFUNCTION("""COMPUTED_VALUE"""),0.74) -> 0.74 | H11: =IFERROR(__xludf.DUMMYFUNCTION("""COMPUTED_VALUE"""),7.0) -> 7 | J11: =IFERROR(__xludf.DUMMYFUNCTION("""COMPUTED_VALUE"""),4.0) -> 4 | K11: =IFERROR(__xludf.DUMMYFUNCTION("""COMPUTED_VALUE"""),"Max 3 per Room") -> Max 3 per Room | L11: =IFERROR(__xludf.DUMMYFUNCTION("""COMPUTED_VALUE"""),"British Virgin Islands") -> British Virgin Islands | M11: =IFERROR(__xludf.DUMMYFUNCTION("""COMPUTED_VALUE"""),"Guana Island") -> Guana Island | N11: =IFERROR(__xludf.DUMMYFUNCTION("""COMPUTED_VALUE"""),"Beef Island") -> Beef Island | O11: =IFERROR(__xludf.DUMMYFUNCTION("""COMPUTED_VALUE"""),FALSE) -> FALSE | R11: =IFERROR(__xludf.DUMMYFUNCTION("""COMPUTED_VALUE"""),"Quiet") -> Quiet | S11: =IFERROR(__xludf.DUMMYFUNCTION("""COMPUTED_VALUE"""),"Beach, Swim Out/Plunge Pool Rooms, Family Suite, 2 Bedroom Suites, Wifi (Paid), Tennis, Snorkelling, Buffet") -> Beach, Swim Out/Plunge Pool Rooms, Family Suite, 2 Bedroom Suites, Wifi (Paid), Tennis, Snorkelling, Buffet | T11: =IFERROR(__xludf.DUMMYFUNCTION("""COMPUTED_VALUE"""),"Can't Book Two Rooms") -> Can't Book Two Rooms | U11: =IFERROR(__xludf.DUMMYFUNCTION("""COMPUTED_VALUE"""),"1 King") -> 1 King | V11: =IFERROR(__xludf.DUMMYFUNCTION("""COMPUTED_VALUE"""),FALSE) -> FALSE | W11: =IFERROR(__xludf.DUMMYFUNCTION("""COMPUTED_VALUE"""),18.0) -> 18 | X11: =IFERROR(__xludf.DUMMYFUNCTION("""COMPUTED_VALUE"""),1930.0) -> 1930 | Y11: =IFERROR(__xludf.DUMMYFUNCTION("""COMPUTED_VALUE"""),2011.0) -> 2011 | Z11: =IFERROR(__xludf.DUMMYFUNCTION("""COMPUTED_VALUE"""),1.0) -> 1
A12: =IFERROR(__xludf.DUMMYFUNCTION("""COMPUTED_VALUE"""),"Serenity at Coconut Bay") -> Serenity at Coconut Bay | B12: =IFERROR(__xludf.DUMMYFUNCTION("""COMPUTED_VALUE"""),97.8) -> 97.8 | C12: =IFERROR(__xludf.DUMMYFUNCTION("""COMPUTED_VALUE"""),"Adults Only") -> Adults Only | D12: =IFERROR(__xludf.DUMMYFUNCTION("""COMPUTED_VALUE"""),22400.0) -> 22400 | E12: =IFERROR(__xludf.DUMMYFUNCTION("""COMPUTED_VALUE"""),30935.517759999995) -> 30935.518 | F12: =IFERROR(__xludf.DUMMYFUNCTION("""COMPUTED_VALUE"""),0.79) -> 0.79 | H12: =IFERROR(__xludf.DUMMYFUNCTION("""COMPUTED_VALUE"""),9.0) -> 9 | J12: =IFERROR(__xludf.DUMMYFUNCTION("""COMPUTED_VALUE"""),5.0) -> 5 | L12: =IFERROR(__xludf.DUMMYFUNCTION("""COMPUTED_VALUE"""),"Saint Lucia") -> Saint Lucia | M12: =IFERROR(__xludf.DUMMYFUNCTION("""COMPUTED_VALUE"""),"Vieux Fort") -> Vieux Fort | N12: =IFERROR(__xludf.DUMMYFUNCTION("""COMPUTED_VALUE"""),"Hewanorra") -> Hewanorra | O12: =IFERROR(__xludf.DUMMYFUNCTION("""COMPUTED_VALUE"""),FALSE) -> FALSE | P12: =IFERROR(__xludf.DUMMYFUNCTION("""COMPUTED_VALUE"""),0.003472222222222222) -> 0.0034722222 | R12: =IFERROR(__xludf.DUMMYFUNCTION("""COMPUTED_VALUE"""),"Luxury") -> Luxury | S12: =IFERROR(__xludf.DUMMYFUNCTION("""COMPUTED_VALUE"""),"Beach, Swim Out/Plunge Pool Rooms, Gym, Spa, Wifi (Free), Tennis, Snorkelling, Room Service, Evening Entertainment") -> Beach, Swim Out/Plunge Pool Rooms, Gym, Spa, Wifi (Free), Tennis, Snorkelling, Room Service, Evening Entertainment | V12: =IFERROR(__xludf.DUMMYFUNCTION("""COMPUTED_VALUE"""),FALSE) -> FALSE | W12: =IFERROR(__xludf.DUMMYFUNCTION("""COMPUTED_VALUE"""),36.0) -> 36
A13: =IFERROR(__xludf.DUMMYFUNCTION("""COMPUTED_VALUE"""),"Fairmont Heritage Place Mayakoba") -> Fairmont Heritage Place Mayakoba | B13: =IFERROR(__xludf.DUMMYFUNCTION("""COMPUTED_VALUE"""),97.7) -> 97.7 | C13: =IFERROR(__xludf.DUMMYFUNCTION("""COMPUTED_VALUE"""),"Family") -> Family | D13: =IFERROR(__xludf.DUMMYFUNCTION("""COMPUTED_VALUE"""),28355.67) -> 28355.67 | E13: =IFERROR(__xludf.DUMMYFUNCTION("""COMPUTED_VALUE"""),39160.59521793299) -> 39160.595 | F13: =IFERROR(__xludf.DUMMYFUNCTION("""COMPUTED_VALUE"""),0.62) -> 0.62 | G13: =IFERROR(__xludf.DUMMYFUNCTION("""COMPUTED_VALUE"""),5.0) -> 5 | H13: =IFERROR(__xludf.DUMMYFUNCTION("""COMPUTED_VALUE"""),9.0) -> 9 | J13: =IFERROR(__xludf.DUMMYFUNCTION("""COMPUTED_VALUE"""),5.0) -> 5 | L13: =IFERROR(__xludf.DUMMYFUNCTION("""COMPUTED_VALUE"""),"Mexico") -> Mexico | M13: =IFERROR(__xludf.DUMMYFUNCTION("""COMPUTED_VALUE"""),"Playa del Carmen") -> Playa del Carmen | N13: =IFERROR(__xludf.DUMMYFUNCTION("""COMPUTED_VALUE"""),"Cancun") -> Cancun | O13: =IFERROR(__xludf.DUMMYFUNCTION("""COMPUTED_VALUE"""),TRUE) -> TRUE | P13: =IFERROR(__xludf.DUMMYFUNCTION("""COMPUTED_VALUE"""),0.02847222222222222) -> 0.028472222 | Q13: =IFERROR(__xludf.DUMMYFUNCTION("""COMPUTED_VALUE"""),"Fairmont") -> Fairmont | R13: =IFERROR(__xludf.DUMMYFUNCTION("""COMPUTED_VALUE"""),"Luxury, Business") -> Luxury, Business | S13: =IFERROR(__xludf.DUMMYFUNCTION("""COMPUTED_VALUE"""),"Beach, Family Suite, 2 Bedroom Suites, Kids Club, Gym, Golf Course, Tennis, Spa, Wifi (Free), Babysitting, Archery, Snorkelling, Windsurfing, Pets Allowed, Bicycles Available, Hiking, Watersports Equipment Rentals, Yoga Classes, Room Service, Evening Ente"&"rtainment") -> Beach, Family Suite, 2 Bedroom Suites, Kids Club, Gym, Golf Course, Tennis, Spa, Wifi (Free), Babysitting, Archery, Snorkelling, Windsurfing, Pets Allowed, Bicycles Available, Hiking, Watersports Equipment Rentals, Yoga Classes, Room Service, Evening Entertainment | U13: =IFERROR(__xludf.DUMMYFUNCTION("""COMPUTED_VALUE"""),"2 King and 2 Twin w Trundle") -> 2 King and 2 Twin w Trundle | V13: =IFERROR(__xludf.DUMMYFUNCTION("""COMPUTED_VALUE"""),FALSE) -> FALSE | W13: =IFERROR(__xludf.DUMMYFUNCTION("""COMPUTED_VALUE"""),401.0) -> 401 | X13: =IFERROR(__xludf.DUMMYFUNCTION("""COMPUTED_VALUE"""),2006.0) -> 2006 | Y13: =IFERROR(__xludf.DUMMYFUNCTION("""COMPUTED_VALUE"""),2022.0) -> 2022 | Z13: =IFERROR(__xludf.DUMMYFUNCTION("""COMPUTED_VALUE"""),2.0) -> 2
A14: =IFERROR(__xludf.DUMMYFUNCTION("""COMPUTED_VALUE"""),"Villa on Dunbar Rock") -> Villa on Dunbar Rock | B14: =IFERROR(__xludf.DUMMYFUNCTION("""COMPUTED_VALUE"""),97.5) -> 97.5 | C14: =IFERROR(__xludf.DUMMYFUNCTION("""COMPUTED_VALUE"""),"Adults Only") -> Adults Only | D14: =IFERROR(__xludf.DUMMYFUNCTION("""COMPUTED_VALUE"""),4867.14) -> 4867.14 | E14: =IFERROR(__xludf.DUMMYFUNCTION("""COMPUTED_VALUE"""),6721.763210286) -> 6721.7632 | F14: =IFERROR(__xludf.DUMMYFUNCTION("""COMPUTED_VALUE"""),3.6) -> 3.6 | L14: =IFERROR(__xludf.DUMMYFUNCTION("""COMPUTED_VALUE"""),"Honduras") -> Honduras | M14: =IFERROR(__xludf.DUMMYFUNCTION("""COMPUTED_VALUE"""),"Guanaja") -> Guanaja | N14: =IFERROR(__xludf.DUMMYFUNCTION("""COMPUTED_VALUE"""),"Roatan") -> Roatan | O14: =IFERROR(__xludf.DUMMYFUNCTION("""COMPUTED_VALUE"""),FALSE) -> FALSE | R14: =IFERROR(__xludf.DUMMYFUNCTION("""COMPUTED_VALUE"""),"Harbour View, Bay View") -> Harbour View, Bay View | S14: =IFERROR(__xludf.DUMMYFUNCTION("""COMPUTED_VALUE"""),"Beach, Wifi (Free), Gym, Diving, Snorkelling") -> Beach, Wifi (Free), Gym, Diving, Snorkelling | V14: =IFERROR(__xludf.DUMMYFUNCTION("""COMPUTED_VALUE"""),FALSE) -> FALSE
A15: =IFERROR(__xludf.DUMMYFUNCTION("""COMPUTED_VALUE"""),"Hammock Cove Antigua") -> Hammock Cove Antigua | B15: =IFERROR(__xludf.DUMMYFUNCTION("""COMPUTED_VALUE"""),97.3) -> 97.3 | C15: =IFERROR(__xludf.DUMMYFUNCTION("""COMPUTED_VALUE"""),"Adults Only") -> Adults Only | D15: =IFERROR(__xludf.DUMMYFUNCTION("""COMPUTED_VALUE"""),10155.6) -> 10155.6 | E15: =IFERROR(__xludf.DUMMYFUNCTION("""COMPUTED_VALUE"""),14025.390364439998) -> 14025.39 | F15: =IFERROR(__xludf.DUMMYFUNCTION("""COMPUTED_VALUE"""),1.7) -> 1.7 | H15: =IFERROR(__xludf.DUMMYFUNCTION("""COMPUTED_VALUE"""),7.0) -> 7 | L15: =IFERROR(__xludf.DUMMYFUNCTION("""COMPUTED_VALUE"""),"Antigua") -> Antigua | M15: =IFERROR(__xludf.DUMMYFUNCTION("""COMPUTED_VALUE"""),"Antigua") -> Antigua | N15: =IFERROR(__xludf.DUMMYFUNCTION("""COMPUTED_VALUE"""),"V.C. Bird") -> V.C. Bird | O15: =IFERROR(__xludf.DUMMYFUNCTION("""COMPUTED_VALUE"""),TRUE) -> TRUE | P15: =IFERROR(__xludf.DUMMYFUNCTION("""COMPUTED_VALUE"""),0.021527777777777778) -> 0.021527778 | R15: =IFERROR(__xludf.DUMMYFUNCTION("""COMPUTED_VALUE"""),"Romantic") -> Romantic | S15: =IFERROR(__xludf.DUMMYFUNCTION("""COMPUTED_VALUE"""),"Beach, Gym, Diving, Spa, Wifi (Free), Snorkelling, Fishing, Hiking, Watersports Equipment Rentals, Yoga Classes, Room Service") -> Beach, Gym, Diving, Spa, Wifi (Free), Snorkelling, Fishing, Hiking, Watersports Equipment Rentals, Yoga Classes, Room Service | V15: =IFERROR(__xludf.DUMMYFUNCTION("""COMPUTED_VALUE"""),FALSE) -> FALSE | W15: =IFERROR(__xludf.DUMMYFUNCTION("""COMPUTED_VALUE"""),42.0) -> 42 | X15: =IFERROR(__xludf.DUMMYFUNCTION("""COMPUTED_VALUE"""),2019.0) -> 2019 | Z15: =IFERROR(__xludf.DUMMYFUNCTION("""COMPUTED_VALUE"""),1.0) -> 1
A16: =IFERROR(__xludf.DUMMYFUNCTION("""COMPUTED_VALUE"""),"Grand Velas Los Cabos") -> Grand Velas Los Cabos | B16: =IFERROR(__xludf.DUMMYFUNCTION("""COMPUTED_VALUE"""),97.3) -> 97.3 | C16: =IFERROR(__xludf.DUMMYFUNCTION("""COMPUTED_VALUE"""),"Family") -> Family | D16: =IFERROR(__xludf.DUMMYFUNCTION("""COMPUTED_VALUE"""),13584.0) -> 13584 | E16: =IFERROR(__xludf.DUMMYFUNCTION("""COMPUTED_VALUE"""),18760.1818416) -> 18760.182 | F16: =IFERROR(__xludf.DUMMYFUNCTION("""COMPUTED_VALUE"""),1.27) -> 1.27 | G16: =IFERROR(__xludf.DUMMYFUNCTION("""COMPUTED_VALUE"""),5.0) -> 5 | H16: =IFERROR(__xludf.DUMMYFUNCTION("""COMPUTED_VALUE"""),9.0) -> 9 | J16: =IFERROR(__xludf.DUMMYFUNCTION("""COMPUTED_VALUE"""),5.0) -> 5 | L16: =IFERROR(__xludf.DUMMYFUNCTION("""COMPUTED_VALUE"""),"Mexico") -> Mexico | M16: =IFERROR(__xludf.DUMMYFUNCTION("""COMPUTED_VALUE"""),"Cabo San Lucas") -> Cabo San Lucas | N16: =IFERROR(__xludf.DUMMYFUNCTION("""COMPUTED_VALUE"""),"Los Cabos") -> Los Cabos | O16: =IFERROR(__xludf.DUMMYFUNCTION("""COMPUTED_VALUE"""),TRUE) -> TRUE | P16: =IFERROR(__xludf.DUMMYFUNCTION("""COMPUTED_VALUE"""),0.021527777777777778) -> 0.021527778 | Q16: =IFERROR(__xludf.DUMMYFUNCTION("""COMPUTED_VALUE"""),"Velas Resorts") -> Velas Resorts | R16: =IFERROR(__xludf.DUMMYFUNCTION("""COMPUTED_VALUE"""),"Family") -> Family | S16: =IFERROR(__xludf.DUMMYFUNCTION("""COMPUTED_VALUE"""),"Beach, Great Food, Swim Out/Plunge Pool Rooms, Family Suite, 2 Bedroom Suites, Kids Club, Teen Club, Heated Pool, Gym, Spa, Wifi (Free), Babysitting, Adult Pool, Swim Up Bar, Room Service, Evening Entertainment") -> Beach, Great Food, Swim Out/Plunge Pool Rooms, Family Suite, 2 Bedroom Suites, Kids Club, Teen Club, Heated Pool, Gym, Spa, Wifi (Free), Babysitting, Adult Pool, Swim Up Bar, Room Service, Evening Entertainment | U16: =IFERROR(__xludf.DUMMYFUNCTION("""COMPUTED_VALUE"""),"1 King or 2 Queen") -> 1 King or 2 Queen | V16: =IFERROR(__xludf.DUMMYFUNCTION("""COMPUTED_VALUE"""),TRUE) -> TRUE | W16: =IFERROR(__xludf.DUMMYFUNCTION("""COMPUTED_VALUE"""),304.0) -> 304 | X16: =IFERROR(__xludf.DUMMYFUNCTION("""COMPUTED_VALUE"""),2016.0) -> 2016
A17: =IFERROR(__xludf.DUMMYFUNCTION("""COMPUTED_VALUE"""),"Calabash Hotel (Jan 15 to Mar 15 12+ Allowed, Mar 16 to Dec 20 6+ Allowed, Dec 21 to Jan 14 No age limit)") -> Calabash Hotel (Jan 15 to Mar 15 12+ Allowed, Mar 16 to Dec 20 6+ Allowed, Dec 21 to Jan 14 No age limit) | B17: =IFERROR(__xludf.DUMMYFUNCTION("""COMPUTED_VALUE"""),97.3) -> 97.3 | C17: =IFERROR(__xludf.DUMMYFUNCTION("""COMPUTED_VALUE"""),"Family") -> Family | D17: =IFERROR(__xludf.DUMMYFUNCTION("""COMPUTED_VALUE"""),14420.12) -> 14420.12 | E17: =IFERROR(__xludf.DUMMYFUNCTION("""COMPUTED_VALUE"""),19914.905283988) -> 19914.905 | F17: =IFERROR(__xludf.DUMMYFUNCTION("""COMPUTED_VALUE"""),1.2) -> 1.2 | G17: =IFERROR(__xludf.DUMMYFUNCTION("""COMPUTED_VALUE"""),4.0) -> 4 | H17: =IFERROR(__xludf.DUMMYFUNCTION("""COMPUTED_VALUE"""),9.0) -> 9 | J17: =IFERROR(__xludf.DUMMYFUNCTION("""COMPUTED_VALUE"""),5.0) -> 5 | K17: =IFERROR(__xludf.DUMMYFUNCTION("""COMPUTED_VALUE"""),"Can't Book Kids Online") -> Can't Book Kids Online | L17: =IFERROR(__xludf.DUMMYFUNCTION("""COMPUTED_VALUE"""),"Grenada") -> Grenada | M17: =IFERROR(__xludf.DUMMYFUNCTION("""COMPUTED_VALUE"""),"Lance aux Epines") -> Lance aux Epines | N17: =IFERROR(__xludf.DUMMYFUNCTION("""COMPUTED_VALUE"""),"Point Saline") -> Point Saline | O17: =IFERROR(__xludf.DUMMYFUNCTION("""COMPUTED_VALUE"""),FALSE) -> FALSE | P17: =IFERROR(__xludf.DUMMYFUNCTION("""COMPUTED_VALUE"""),0.005555555555555556) -> 0.0055555556 | R17: =IFERROR(__xludf.DUMMYFUNCTION("""COMPUTED_VALUE"""),"Boutique, Great View") -> Boutique, Great View | S17: =IFERROR(__xludf.DUMMYFUNCTION("""COMPUTED_VALUE"""),"Beach, Swim Out/Plunge Pool Rooms, Gym, Diving, Wifi (Free), Babysitting, Tennis, Snorkelling, Yoga Classes, Room Service") -> Beach, Swim Out/Plunge Pool Rooms, Gym, Diving, Wifi (Free), Babysitting, Tennis, Snorkelling, Yoga Classes, Room Service | T17: =IFERROR(__xludf.DUMMYFUNCTION("""COMPUTED_VALUE"""),"Can Request") -> Can Request | U17: =IFERROR(__xludf.DUMMYFUNCTION("""COMPUTED_VALUE"""),"1 King or 2 Twin") -> 1 King or 2 Twin | V17: =IFERROR(__xludf.DUMMYFUNCTION("""COMPUTED_VALUE"""),FALSE) -> FALSE | W17: =IFERROR(__xludf.DUMMYFUNCTION("""COMPUTED_VALUE"""),30.0) -> 30 | X17: =IFERROR(__xludf.DUMMYFUNCTION("""COMPUTED_VALUE"""),1960.0) -> 1960 | Y17: =IFERROR(__xludf.DUMMYFUNCTION("""COMPUTED_VALUE"""),2022.0) -> 2022 | Z17: =IFERROR(__xludf.DUMMYFUNCTION("""COMPUTED_VALUE"""),2.0) -> 2
A18: =IFERROR(__xludf.DUMMYFUNCTION("""COMPUTED_VALUE"""),"Ambergris Cay Private Island All Inclusive") -> Ambergris Cay Private Island All Inclusive | B18: =IFERROR(__xludf.DUMMYFUNCTION("""COMPUTED_VALUE"""),97.3) -> 97.3 | C18: =IFERROR(__xludf.DUMMYFUNCTION("""COMPUTED_VALUE"""),"Family") -> Family | D18: =IFERROR(__xludf.DUMMYFUNCTION("""COMPUTED_VALUE"""),51097.2) -> 51097.2 | E18: =IFERROR(__xludf.DUMMYFUNCTION("""COMPUTED_VALUE"""),70567.78295027999) -> 70567.783 | F18: =IFERROR(__xludf.DUMMYFUNCTION("""COMPUTED_VALUE"""),0.34) -> 0.34 | J18: =IFERROR(__xludf.DUMMYFUNCTION("""COMPUTED_VALUE"""),5.0) -> 5 | L18: =IFERROR(__xludf.DUMMYFUNCTION("""COMPUTED_VALUE"""),"Turks and Caicos") -> Turks and Caicos | M18: =IFERROR(__xludf.DUMMYFUNCTION("""COMPUTED_VALUE"""),"Big Ambergris Cay") -> Big Ambergris Cay | N18: =IFERROR(__xludf.DUMMYFUNCTION("""COMPUTED_VALUE"""),"Providenciales") -> Providenciales | O18: =IFERROR(__xludf.DUMMYFUNCTION("""COMPUTED_VALUE"""),TRUE) -> TRUE | R18: =IFERROR(__xludf.DUMMYFUNCTION("""COMPUTED_VALUE"""),"Business, Romantic") -> Business, Romantic | S18: =IFERROR(__xludf.DUMMYFUNCTION("""COMPUTED_VALUE"""),"Gym, Bicycles Available, Hiking, Snorkelling, Watersports Equipment Rentals, Evening Entertainment, Wifi (Free), Yoga Classes, Heated Pool, Swim Out/Plunge Pool Rooms, Room Service, Tennis, Windsurfing, Fishing, Babysitting, Spa, 2 Bedroom Suites, Beach, "&"Kids Club") -> Gym, Bicycles Available, Hiking, Snorkelling, Watersports Equipment Rentals, Evening Entertainment, Wifi (Free), Yoga Classes, Heated Pool, Swim Out/Plunge Pool Rooms, Room Service, Tennis, Windsurfing, Fishing, Babysitting, Spa, 2 Bedroom Suites, Beach, Kids Club | U18: =IFERROR(__xludf.DUMMYFUNCTION("""COMPUTED_VALUE"""),"3 Bedrooms") -> 3 Bedrooms | V18: =IFERROR(__xludf.DUMMYFUNCTION("""COMPUTED_VALUE"""),FALSE) -> FALSE
A19: =IFERROR(__xludf.DUMMYFUNCTION("""COMPUTED_VALUE"""),"La Casa de La Playa (16+ Allowed)") -> La Casa de La Playa (16+ Allowed) | B19: =IFERROR(__xludf.DUMMYFUNCTION("""COMPUTED_VALUE"""),96.8) -> 96.8 | C19: =IFERROR(__xludf.DUMMYFUNCTION("""COMPUTED_VALUE"""),"Adults Only") -> Adults Only | D19: =IFERROR(__xludf.DUMMYFUNCTION("""COMPUTED_VALUE"""),22948.44) -> 22948.44 | E19: =IFERROR(__xludf.DUMMYFUNCTION("""COMPUTED_VALUE"""),31692.940767155993) -> 31692.941 | F19: =IFERROR(__xludf.DUMMYFUNCTION("""COMPUTED_VALUE"""),0.73) -> 0.73 | H19: =IFERROR(__xludf.DUMMYFUNCTION("""COMPUTED_VALUE"""),"NYR") -> NYR | J19: =IFERROR(__xludf.DUMMYFUNCTION("""COMPUTED_VALUE"""),5.0) -> 5 | K19: =IFERROR(__xludf.DUMMYFUNCTION("""COMPUTED_VALUE"""),"16+ Allowed") -> 16+ Allowed | L19: =IFERROR(__xludf.DUMMYFUNCTION("""COMPUTED_VALUE"""),"Mexico") -> Mexico | M19: =IFERROR(__xludf.DUMMYFUNCTION("""COMPUTED_VALUE"""),"Playa del Carmen") -> Playa del Carmen | N19: =IFERROR(__xludf.DUMMYFUNCTION("""COMPUTED_VALUE"""),"Cancun") -> Cancun | O19: =IFERROR(__xludf.DUMMYFUNCTION("""COMPUTED_VALUE"""),TRUE) -> TRUE | P19: =IFERROR(__xludf.DUMMYFUNCTION("""COMPUTED_VALUE"""),0.04027777777777778) -> 0.040277778 | Q19: =IFERROR(__xludf.DUMMYFUNCTION("""COMPUTED_VALUE"""),"Hoteles Xcaret") -> Hoteles Xcaret | R19: =IFERROR(__xludf.DUMMYFUNCTION("""COMPUTED_VALUE"""),"Luxury") -> Luxury | S19: =IFERROR(__xludf.DUMMYFUNCTION("""COMPUTED_VALUE"""),"Beach, Gym, Wifi (Free), Swim Up Bar, Spa, Bicycles Available, Pets Allowed, Snorkelling, Yoga Classes, Room Service") -> Beach, Gym, Wifi (Free), Swim Up Bar, Spa, Bicycles Available, Pets Allowed, Snorkelling, Yoga Classes, Room Service | V19: =IFERROR(__xludf.DUMMYFUNCTION("""COMPUTED_VALUE"""),FALSE) -> FALSE | W19: =IFERROR(__xludf.DUMMYFUNCTION("""COMPUTED_VALUE"""),63.0) -> 63 | X19: =IFERROR(__xludf.DUMMYFUNCTION("""COMPUTED_VALUE"""),2021.0) -> 2021
A20: =IFERROR(__xludf.DUMMYFUNCTION("""COMPUTED_VALUE"""),"Beloved Playa Mujeres (Couples only)") -> Beloved Playa Mujeres (Couples only) | B20: =IFERROR(__xludf.DUMMYFUNCTION("""COMPUTED_VALUE"""),96.7) -> 96.7 | C20: =IFERROR(__xludf.DUMMYFUNCTION("""COMPUTED_VALUE"""),"Adults Only") -> Adults Only | D20: =IFERROR(__xludf.DUMMYFUNCTION("""COMPUTED_VALUE"""),4052.0) -> 4052 | E20: =IFERROR(__xludf.DUMMYFUNCTION("""COMPUTED_VALUE"""),5596.014194799999) -> 5596.0142 | F20: =IFERROR(__xludf.DUMMYFUNCTION("""COMPUTED_VALUE"""),4.12) -> 4.12 | H20: =IFERROR(__xludf.DUMMYFUNCTION("""COMPUTED_VALUE"""),9.0) -> 9 | J20: =IFERROR(__xludf.DUMMYFUNCTION("""COMPUTED_VALUE"""),5.0) -> 5 | K20: =IFERROR(__xludf.DUMMYFUNCTION("""COMPUTED_VALUE"""),"Couples Only") -> Couples Only | L20: =IFERROR(__xludf.DUMMYFUNCTION("""COMPUTED_VALUE"""),"Mexico") -> Mexico | M20: =IFERROR(__xludf.DUMMYFUNCTION("""COMPUTED_VALUE"""),"Playa Mujeres") -> Playa Mujeres | N20: =IFERROR(__xludf.DUMMYFUNCTION("""COMPUTED_VALUE"""),"Cancun") -> Cancun | O20: =IFERROR(__xludf.DUMMYFUNCTION("""COMPUTED_VALUE"""),TRUE) -> TRUE | P20: =IFERROR(__xludf.DUMMYFUNCTION("""COMPUTED_VALUE"""),0.025) -> 0.025 | Q20: =IFERROR(__xludf.DUMMYFUNCTION("""COMPUTED_VALUE"""),"The Excellence Collection") -> The Excellence Collection | R20: =IFERROR(__xludf.DUMMYFUNCTION("""COMPUTED_VALUE"""),"Boutique, Modern") -> Boutique, Modern | S20: =IFERROR(__xludf.DUMMYFUNCTION("""COMPUTED_VALUE"""),"Beach, Swim Out/Plunge Pool Rooms, Heated Pool, Gym, Diving, Spa, Wifi (Free), Swim Up Bar, Snorkelling, Room Service, Buffet") -> Beach, Swim Out/Plunge Pool Rooms, Heated Pool, Gym, Diving, Spa, Wifi (Free), Swim Up Bar, Snorkelling, Room Service, Buffet | V20: =IFERROR(__xludf.DUMMYFUNCTION("""COMPUTED_VALUE"""),FALSE) -> FALSE | W20: =IFERROR(__xludf.DUMMYFUNCTION("""COMPUTED_VALUE"""),109.0) -> 109 | X20: =IFERROR(__xludf.DUMMYFUNCTION("""COMPUTED_VALUE"""),2009.0) -> 2009 | Z20: =IFERROR(__xludf.DUMMYFUNCTION("""COMPUTED_VALUE"""),4.0) -> 4
A21: =IFERROR(__xludf.DUMMYFUNCTION("""COMPUTED_VALUE"""),"Small Hope Bay Lodge (No TV)") -> Small Hope Bay Lodge (No TV) | B21: =IFERROR(__xludf.DUMMYFUNCTION("""COMPUTED_VALUE"""),96.7) -> 96.7 | C21: =IFERROR(__xludf.DUMMYFUNCTION("""COMPUTED_VALUE"""),"Family") -> Family | D21: =IFERROR(__xludf.DUMMYFUNCTION("""COMPUTED_VALUE"""),8855.0) -> 8855 | E21: =IFERROR(__xludf.DUMMYFUNCTION("""COMPUTED_VALUE"""),12229.196864499998) -> 12229.197 | F21: =IFERROR(__xludf.DUMMYFUNCTION("""COMPUTED_VALUE"""),1.89) -> 1.89 | H21: =IFERROR(__xludf.DUMMYFUNCTION("""COMPUTED_VALUE"""),3.0) -> 3 | J21: =IFERROR(__xludf.DUMMYFUNCTION("""COMPUTED_VALUE"""),3.0) -> 3 | K21: =IFERROR(__xludf.DUMMYFUNCTION("""COMPUTED_VALUE"""),"No TV") -> No TV | L21: =IFERROR(__xludf.DUMMYFUNCTION("""COMPUTED_VALUE"""),"Bahamas") -> Bahamas | M21: =IFERROR(__xludf.DUMMYFUNCTION("""COMPUTED_VALUE"""),"Andros") -> Andros | N21: =IFERROR(__xludf.DUMMYFUNCTION("""COMPUTED_VALUE"""),"Lynden Pindling") -> Lynden Pindling | O21: =IFERROR(__xludf.DUMMYFUNCTION("""COMPUTED_VALUE"""),TRUE) -> TRUE | R21: =IFERROR(__xludf.DUMMYFUNCTION("""COMPUTED_VALUE"""),"Bay View, Romantic") -> Bay View, Romantic | S21: =IFERROR(__xludf.DUMMYFUNCTION("""COMPUTED_VALUE"""),"Beach, Family Suite, 2 Bedroom Suites, Babysitting, Diving, Wifi (Free), Fishing, Bicycles Available, Snorkelling, Pets Allowed, Buffet") -> Beach, Family Suite, 2 Bedroom Suites, Babysitting, Diving, Wifi (Free), Fishing, Bicycles Available, Snorkelling, Pets Allowed, Buffet | U21: =IFERROR(__xludf.DUMMYFUNCTION("""COMPUTED_VALUE"""),"1 King and 3 Twin") -> 1 King and 3 Twin | V21: =IFERROR(__xludf.DUMMYFUNCTION("""COMPUTED_VALUE"""),FALSE) -> FALSE | W21: =IFERROR(__xludf.DUMMYFUNCTION("""COMPUTED_VALUE"""),21.0) -> 21 | X21: =IFERROR(__xludf.DUMMYFUNCTION("""COMPUTED_VALUE"""),1960.0) -> 1960 | Y21: =IFERROR(__xludf.DUMMYFUNCTION("""COMPUTED_VALUE"""),2013.0) -> 2013 | Z21: =IFERROR(__xludf.DUMMYFUNCTION("""COMPUTED_VALUE"""),1.0) -> 1
A22: =IFERROR(__xludf.DUMMYFUNCTION("""COMPUTED_VALUE"""),"Palmaïa The House of AïA All Inclusive Wellness Resort (Vegan)") -> Palmaïa The House of AïA All Inclusive Wellness Resort (Vegan) | B22: =IFERROR(__xludf.DUMMYFUNCTION("""COMPUTED_VALUE"""),96.7) -> 96.7 | C22: =IFERROR(__xludf.DUMMYFUNCTION("""COMPUTED_VALUE"""),"Family") -> Family | D22: =IFERROR(__xludf.DUMMYFUNCTION("""COMPUTED_VALUE"""),13423.9) -> 13423.9 | E22: =IFERROR(__xludf.DUMMYFUNCTION("""COMPUTED_VALUE"""),18539.07575261) -> 18539.076 | F22: =IFERROR(__xludf.DUMMYFUNCTION("""COMPUTED_VALUE"""),1.24) -> 1.24 | H22: =IFERROR(__xludf.DUMMYFUNCTION("""COMPUTED_VALUE"""),9.0) -> 9 | J22: =IFERROR(__xludf.DUMMYFUNCTION("""COMPUTED_VALUE"""),5.0) -> 5 | K22: =IFERROR(__xludf.DUMMYFUNCTION("""COMPUTED_VALUE"""),"Vegan") -> Vegan | L22: =IFERROR(__xludf.DUMMYFUNCTION("""COMPUTED_VALUE"""),"Mexico") -> Mexico | M22: =IFERROR(__xludf.DUMMYFUNCTION("""COMPUTED_VALUE"""),"Playa del Carmen") -> Playa del Carmen | N22: =IFERROR(__xludf.DUMMYFUNCTION("""COMPUTED_VALUE"""),"Cancun") -> Cancun | O22: =IFERROR(__xludf.DUMMYFUNCTION("""COMPUTED_VALUE"""),TRUE) -> TRUE | P22: =IFERROR(__xludf.DUMMYFUNCTION("""COMPUTED_VALUE"""),0.041666666666666664) -> 0.041666667 | R22: =IFERROR(__xludf.DUMMYFUNCTION("""COMPUTED_VALUE"""),"Romantic, Luxury") -> Romantic, Luxury | S22: =IFERROR(__xludf.DUMMYFUNCTION("""COMPUTED_VALUE"""),"Beach, Family Suite, 2 Bedroom Suites, Kids Club, Gym, Swim Up Bar, Spa, Wifi (Free), Babysitting, Diving, Bicycles Available, Snorkelling, Yoga Classes, Room Service") -> Beach, Family Suite, 2 Bedroom Suites, Kids Club, Gym, Swim Up Bar, Spa, Wifi (Free), Babysitting, Diving, Bicycles Available, Snorkelling, Yoga Classes, Room Service | U22: =IFERROR(__xludf.DUMMYFUNCTION("""COMPUTED_VALUE"""),"1 King and 1 Bunk Bed") -> 1 King and 1 Bunk Bed | V22: =IFERROR(__xludf.DUMMYFUNCTION("""COMPUTED_VALUE"""),FALSE) -> FALSE | W22: =IFERROR(__xludf.DUMMYFUNCTION("""COMPUTED_VALUE"""),234.0) -> 234 | X22: =IFERROR(__xludf.DUMMYFUNCTION("""COMPUTED_VALUE"""),2019.0) -> 2019 | Z22: =IFERROR(__xludf.DUMMYFUNCTION("""COMPUTED_VALUE"""),4.0) -> 4
A23: =IFERROR(__xludf.DUMMYFUNCTION("""COMPUTED_VALUE"""),"Palafitos Overwater Bungalows") -> Palafitos Overwater Bungalows | B23: =IFERROR(__xludf.DUMMYFUNCTION("""COMPUTED_VALUE"""),96.7) -> 96.7 | C23: =IFERROR(__xludf.DUMMYFUNCTION("""COMPUTED_VALUE"""),"Adults Only") -> Adults Only | D23: =IFERROR(__xludf.DUMMYFUNCTION("""COMPUTED_VALUE"""),16352.0) -> 16352 | E23: =IFERROR(__xludf.DUMMYFUNCTION("""COMPUTED_VALUE"""),22582.927964799997) -> 22582.928 | F23: =IFERROR(__xludf.DUMMYFUNCTION("""COMPUTED_VALUE"""),1.02) -> 1.02 | H23: =IFERROR(__xludf.DUMMYFUNCTION("""COMPUTED_VALUE"""),"NYR") -> NYR | J23: =IFERROR(__xludf.DUMMYFUNCTION("""COMPUTED_VALUE"""),5.0) -> 5 | L23: =IFERROR(__xludf.DUMMYFUNCTION("""COMPUTED_VALUE"""),"Mexico") -> Mexico | M23: =IFERROR(__xludf.DUMMYFUNCTION("""COMPUTED_VALUE"""),"Playa del Carmen") -> Playa del Carmen | N23: =IFERROR(__xludf.DUMMYFUNCTION("""COMPUTED_VALUE"""),"Cancun") -> Cancun | O23: =IFERROR(__xludf.DUMMYFUNCTION("""COMPUTED_VALUE"""),TRUE) -> TRUE | P23: =IFERROR(__xludf.DUMMYFUNCTION("""COMPUTED_VALUE"""),0.025) -> 0.025 | Q23: =IFERROR(__xludf.DUMMYFUNCTION("""COMPUTED_VALUE"""),"Lomas Hospitality") -> Lomas Hospitality | R23: =IFERROR(__xludf.DUMMYFUNCTION("""COMPUTED_VALUE"""),"Romantic, Luxury") -> Romantic, Luxury | S23: =IFERROR(__xludf.DUMMYFUNCTION("""COMPUTED_VALUE"""),"Beach, Swim Out/Plunge Pool Rooms, Gym, Spa, Wifi (Free), Nightclub, Room Service") -> Beach, Swim Out/Plunge Pool Rooms, Gym, Spa, Wifi (Free), Nightclub, Room Service | V23: =IFERROR(__xludf.DUMMYFUNCTION("""COMPUTED_VALUE"""),FALSE) -> FALSE
A24: =IFERROR(__xludf.DUMMYFUNCTION("""COMPUTED_VALUE"""),"Drake Bay Getaway Resort (Alcohol not included)") -> Drake Bay Getaway Resort (Alcohol not included) | B24: =IFERROR(__xludf.DUMMYFUNCTION("""COMPUTED_VALUE"""),96.5) -> 96.5 | C24: =IFERROR(__xludf.DUMMYFUNCTION("""COMPUTED_VALUE"""),"Family") -> Family | D24: =IFERROR(__xludf.DUMMYFUNCTION("""COMPUTED_VALUE"""),6650.0) -> 6650 | E24: =IFERROR(__xludf.DUMMYFUNCTION("""COMPUTED_VALUE"""),9183.981834999999) -> 9183.9818 | F24: =IFERROR(__xludf.DUMMYFUNCTION("""COMPUTED_VALUE"""),2.48) -> 2.48 | J24: =IFERROR(__xludf.DUMMYFUNCTION("""COMPUTED_VALUE"""),3.0) -> 3 | K24: =IFERROR(__xludf.DUMMYFUNCTION("""COMPUTED_VALUE"""),"Alcohol not included") -> Alcohol not included | L24: =IFERROR(__xludf.DUMMYFUNCTION("""COMPUTED_VALUE"""),"Costa Rica") -> Costa Rica | M24: =IFERROR(__xludf.DUMMYFUNCTION("""COMPUTED_VALUE"""),"Drake Bay") -> Drake Bay | N24: =IFERROR(__xludf.DUMMYFUNCTION("""COMPUTED_VALUE"""),"San Jose Juan Santamaria") -> San Jose Juan Santamaria | O24: =IFERROR(__xludf.DUMMYFUNCTION("""COMPUTED_VALUE"""),TRUE) -> TRUE | P24: =IFERROR(__xludf.DUMMYFUNCTION("""COMPUTED_VALUE"""),0.25277777777777777) -> 0.25277778 | R24: =IFERROR(__xludf.DUMMYFUNCTION("""COMPUTED_VALUE"""),"Modern, Boutique") -> Modern, Boutique | S24: =IFERROR(__xludf.DUMMYFUNCTION("""COMPUTED_VALUE"""),"Beach, Diving, Horseback Riding, Wifi (Free), Hiking, Snorkelling, Fishing") -> Beach, Diving, Horseback Riding, Wifi (Free), Hiking, Snorkelling, Fishing | U24: =IFERROR(__xludf.DUMMYFUNCTION("""COMPUTED_VALUE"""),"1 King and 1 Queen") -> 1 King and 1 Queen | V24: =IFERROR(__xludf.DUMMYFUNCTION("""COMPUTED_VALUE"""),FALSE) -> FALSE
A25: =IFERROR(__xludf.DUMMYFUNCTION("""COMPUTED_VALUE"""),"Jumby Bay Island - An Oetker Collection Hotel") -> Jumby Bay Island - An Oetker Collection Hotel | B25: =IFERROR(__xludf.DUMMYFUNCTION("""COMPUTED_VALUE"""),96.5) -> 96.5 | C25: =IFERROR(__xludf.DUMMYFUNCTION("""COMPUTED_VALUE"""),"Family") -> Family | D25: =IFERROR(__xludf.DUMMYFUNCTION("""COMPUTED_VALUE"""),37871.0) -> 37871 | E25: =IFERROR(__xludf.DUMMYFUNCTION("""COMPUTED_VALUE"""),52301.74076289999) -> 52301.741 | F25: =IFERROR(__xludf.DUMMYFUNCTION("""COMPUTED_VALUE"""),0.44) -> 0.44 | G25: =IFERROR(__xludf.DUMMYFUNCTION("""COMPUTED_VALUE"""),4.0) -> 4 | H25: =IFERROR(__xludf.DUMMYFUNCTION("""COMPUTED_VALUE"""),9.0) -> 9 | L25: =IFERROR(__xludf.DUMMYFUNCTION("""COMPUTED_VALUE"""),"Antigua") -> Antigua | M25: =IFERROR(__xludf.DUMMYFUNCTION("""COMPUTED_VALUE"""),"Long Island") -> Long Island | N25: =IFERROR(__xludf.DUMMYFUNCTION("""COMPUTED_VALUE"""),"V.C. Bird") -> V.C. Bird | O25: =IFERROR(__xludf.DUMMYFUNCTION("""COMPUTED_VALUE"""),TRUE) -> TRUE | P25: =IFERROR(__xludf.DUMMYFUNCTION("""COMPUTED_VALUE"""),0.011805555555555555) -> 0.011805556 | Q25: =IFERROR(__xludf.DUMMYFUNCTION("""COMPUTED_VALUE"""),"Oetker Collection") -> Oetker Collection | R25: =IFERROR(__xludf.DUMMYFUNCTION("""COMPUTED_VALUE"""),"Quiet") -> Quiet | S25: =IFERROR(__xludf.DUMMYFUNCTION("""COMPUTED_VALUE"""),"Beach, Swim Out/Plunge Pool Rooms, Family Suite, 2 Bedroom Suites, Kids Club, Wifi (Free), Babysitting, Snorkelling, Spa, Gym, Bicycles Available, Fishing, Tennis, Buffet") -> Beach, Swim Out/Plunge Pool Rooms, Family Suite, 2 Bedroom Suites, Kids Club, Wifi (Free), Babysitting, Snorkelling, Spa, Gym, Bicycles Available, Fishing, Tennis, Buffet | U25: =IFERROR(__xludf.DUMMYFUNCTION("""COMPUTED_VALUE"""),"1 King and 1 Sofa Bed") -> 1 King and 1 Sofa Bed | V25: =IFERROR(__xludf.DUMMYFUNCTION("""COMPUTED_VALUE"""),FALSE) -> FALSE | W25: =IFERROR(__xludf.DUMMYFUNCTION("""COMPUTED_VALUE"""),42.0) -> 42 | X25: =IFERROR(__xludf.DUMMYFUNCTION("""COMPUTED_VALUE"""),1984.0) -> 1984 | Y25: =IFERROR(__xludf.DUMMYFUNCTION("""COMPUTED_VALUE"""),2018.0) -> 2018 | Z25: =IFERROR(__xludf.DUMMYFUNCTION("""COMPUTED_VALUE"""),1.0) -> 1
A26: =IFERROR(__xludf.DUMMYFUNCTION("""COMPUTED_VALUE"""),"Grand Velas Boutique Hotel Los Cabos") -> Grand Velas Boutique Hotel Los Cabos | B26: =IFERROR(__xludf.DUMMYFUNCTION("""COMPUTED_VALUE"""),96.3) -> 96.3 | C26: =IFERROR(__xludf.DUMMYFUNCTION("""COMPUTED_VALUE"""),"Adults Only") -> Adults Only | D26: =IFERROR(__xludf.DUMMYFUNCTION("""COMPUTED_VALUE"""),9506.0) -> 9506 | E26: =IFERROR(__xludf.DUMMYFUNCTION("""COMPUTED_VALUE"""),13128.260349399998) -> 13128.26 | F26: =IFERROR(__xludf.DUMMYFUNCTION("""COMPUTED_VALUE"""),1.71) -> 1.71 | H26: =IFERROR(__xludf.DUMMYFUNCTION("""COMPUTED_VALUE"""),"NYR") -> NYR | J26: =IFERROR(__xludf.DUMMYFUNCTION("""COMPUTED_VALUE"""),5.0) -> 5 | L26: =IFERROR(__xludf.DUMMYFUNCTION("""COMPUTED_VALUE"""),"Mexico") -> Mexico | M26: =IFERROR(__xludf.DUMMYFUNCTION("""COMPUTED_VALUE"""),"Los Cabos") -> Los Cabos | N26: =IFERROR(__xludf.DUMMYFUNCTION("""COMPUTED_VALUE"""),"Los Cabos") -> Los Cabos | O26: =IFERROR(__xludf.DUMMYFUNCTION("""COMPUTED_VALUE"""),TRUE) -> TRUE | P26: =IFERROR(__xludf.DUMMYFUNCTION("""COMPUTED_VALUE"""),0.02013888888888889) -> 0.020138889 | Q26: =IFERROR(__xludf.DUMMYFUNCTION("""COMPUTED_VALUE"""),"Velas Resorts") -> Velas Resorts | S26: =IFERROR(__xludf.DUMMYFUNCTION("""COMPUTED_VALUE"""),"Beach, Great Food, Swim Out/Plunge Pool Rooms, Heated Pool, Snorkelling, Fishing, Nightclub, Spa, Gym, Wifi (Free), Yoga Classes, Swim Up Bar, Room Service, Evening Entertainment, Buffet") -> Beach, Great Food, Swim Out/Plunge Pool Rooms, Heated Pool, Snorkelling, Fishing, Nightclub, Spa, Gym, Wifi (Free), Yoga Classes, Swim Up Bar, Room Service, Evening Entertainment, Buffet | V26: =IFERROR(__xludf.DUMMYFUNCTION("""COMPUTED_VALUE"""),TRUE) -> TRUE | W26: =IFERROR(__xludf.DUMMYFUNCTION("""COMPUTED_VALUE"""),79.0) -> 79 | X26: =IFERROR(__xludf.DUMMYFUNCTION("""COMPUTED_VALUE"""),2023.0) -> 2023
A27: =IFERROR(__xludf.DUMMYFUNCTION("""COMPUTED_VALUE"""),"Jade Mountain Resort") -> Jade Mountain Resort | B27: =IFERROR(__xludf.DUMMYFUNCTION("""COMPUTED_VALUE"""),96.3) -> 96.3 | C27: =IFERROR(__xludf.DUMMYFUNCTION("""COMPUTED_VALUE"""),"Adults Only") -> Adults Only | D27: =IFERROR(__xludf.DUMMYFUNCTION("""COMPUTED_VALUE"""),20496.0) -> 20496 | E27: =IFERROR(__xludf.DUMMYFUNCTION("""COMPUTED_VALUE"""),28305.9987504) -> 28305.999 | F27: =IFERROR(__xludf.DUMMYFUNCTION("""COMPUTED_VALUE"""),0.8) -> 0.8 | G27: =IFERROR(__xludf.DUMMYFUNCTION("""COMPUTED_VALUE"""),5.0) -> 5 | H27: =IFERROR(__xludf.DUMMYFUNCTION("""COMPUTED_VALUE"""),9.0) -> 9 | J27: =IFERROR(__xludf.DUMMYFUNCTION("""COMPUTED_VALUE"""),5.0) -> 5 | L27: =IFERROR(__xludf.DUMMYFUNCTION("""COMPUTED_VALUE"""),"Saint Lucia") -> Saint Lucia | M27: =IFERROR(__xludf.DUMMYFUNCTION("""COMPUTED_VALUE"""),"Soufriere") -> Soufriere | N27: =IFERROR(__xludf.DUMMYFUNCTION("""COMPUTED_VALUE"""),"Hewanorra") -> Hewanorra | O27: =IFERROR(__xludf.DUMMYFUNCTION("""COMPUTED_VALUE"""),FALSE) -> FALSE | P27: =IFERROR(__xludf.DUMMYFUNCTION("""COMPUTED_VALUE"""),0.04236111111111111) -> 0.042361111 | R27: =IFERROR(__xludf.DUMMYFUNCTION("""COMPUTED_VALUE"""),"Bay View, Green") -> Bay View, Green | S27: =IFERROR(__xludf.DUMMYFUNCTION("""COMPUTED_VALUE"""),"Beach, Swim Out/Plunge Pool Rooms, Gym, Diving, Tennis, Wifi (Free), Snorkelling, Spa, Room Service") -> Beach, Swim Out/Plunge Pool Rooms, Gym, Diving, Tennis, Wifi (Free), Snorkelling, Spa, Room Service | V27: =IFERROR(__xludf.DUMMYFUNCTION("""COMPUTED_VALUE"""),FALSE) -> FALSE | W27: =IFERROR(__xludf.DUMMYFUNCTION("""COMPUTED_VALUE"""),20.0) -> 20
A28: =IFERROR(__xludf.DUMMYFUNCTION("""COMPUTED_VALUE"""),"Excellence Playa Mujeres") -> Excellence Playa Mujeres | B28: =IFERROR(__xludf.DUMMYFUNCTION("""COMPUTED_VALUE"""),96.0) -> 96 | C28: =IFERROR(__xludf.DUMMYFUNCTION("""COMPUTED_VALUE"""),"Adults Only") -> Adults Only | D28: =IFERROR(__xludf.DUMMYFUNCTION("""COMPUTED_VALUE"""),3666.0) -> 3666 | E28: =IFERROR(__xludf.DUMMYFUNCTION("""COMPUTED_VALUE"""),5062.9289334) -> 5062.9289 | F28: =IFERROR(__xludf.DUMMYFUNCTION("""COMPUTED_VALUE"""),4.36) -> 4.36 | H28: =IFERROR(__xludf.DUMMYFUNCTION("""COMPUTED_VALUE"""),9.0) -> 9 | J28: =IFERROR(__xludf.DUMMYFUNCTION("""COMPUTED_VALUE"""),5.0) -> 5 | L28: =IFERROR(__xludf.DUMMYFUNCTION("""COMPUTED_VALUE"""),"Mexico") -> Mexico | M28: =IFERROR(__xludf.DUMMYFUNCTION("""COMPUTED_VALUE"""),"Playa Mujeres") -> Playa Mujeres | N28: =IFERROR(__xludf.DUMMYFUNCTION("""COMPUTED_VALUE"""),"Cancun") -> Cancun | O28: =IFERROR(__xludf.DUMMYFUNCTION("""COMPUTED_VALUE"""),TRUE) -> TRUE | P28: =IFERROR(__xludf.DUMMYFUNCTION("""COMPUTED_VALUE"""),0.025) -> 0.025 | Q28: =IFERROR(__xludf.DUMMYFUNCTION("""COMPUTED_VALUE"""),"The Excellence Collection") -> The Excellence Collection | R28: =IFERROR(__xludf.DUMMYFUNCTION("""COMPUTED_VALUE"""),"Luxury, Quiet") -> Luxury, Quiet | S28: =IFERROR(__xludf.DUMMYFUNCTION("""COMPUTED_VALUE"""),"Beach, Swim Out/Plunge Pool Rooms, Heated Pool, Gym, Diving, Lazy River, Snorkelling, Wifi (Free), Swim Up Bar, Tennis, Nightclub, Spa, Room Service, Evening Entertainment, Buffet") -> Beach, Swim Out/Plunge Pool Rooms, Heated Pool, Gym, Diving, Lazy River, Snorkelling, Wifi (Free), Swim Up Bar, Tennis, Nightclub, Spa, Room Service, Evening Entertainment, Buffet | V28: =IFERROR(__xludf.DUMMYFUNCTION("""COMPUTED_VALUE"""),FALSE) -> FALSE | W28: =IFERROR(__xludf.DUMMYFUNCTION("""COMPUTED_VALUE"""),450.0) -> 450 | X28: =IFERROR(__xludf.DUMMYFUNCTION("""COMPUTED_VALUE"""),2007.0) -> 2007 | Z28: =IFERROR(__xludf.DUMMYFUNCTION("""COMPUTED_VALUE"""),5.0) -> 5
A29: =IFERROR(__xludf.DUMMYFUNCTION("""COMPUTED_VALUE"""),"Hyatt Zilara Cap Cana") -> Hyatt Zilara Cap Cana | B29: =IFERROR(__xludf.DUMMYFUNCTION("""COMPUTED_VALUE"""),96.0) -> 96 | C29: =IFERROR(__xludf.DUMMYFUNCTION("""COMPUTED_VALUE"""),"Adults Only") -> Adults Only | D29: =IFERROR(__xludf.DUMMYFUNCTION("""COMPUTED_VALUE"""),6653.79) -> 6653.79 | E29: =IFERROR(__xludf.DUMMYFUNCTION("""COMPUTED_VALUE"""),9189.216014120999) -> 9189.216 | F29: =IFERROR(__xludf.DUMMYFUNCTION("""COMPUTED_VALUE"""),2.4) -> 2.4 | G29: =IFERROR(__xludf.DUMMYFUNCTION("""COMPUTED_VALUE"""),4.0) -> 4 | H29: =IFERROR(__xludf.DUMMYFUNCTION("""COMPUTED_VALUE"""),7.0) -> 7 | I29: =IFERROR(__xludf.DUMMYFUNCTION("""COMPUTED_VALUE"""),"F") -> F | J29: =IFERROR(__xludf.DUMMYFUNCTION("""COMPUTED_VALUE"""),5.0) -> 5 | L29: =IFERROR(__xludf.DUMMYFUNCTION("""COMPUTED_VALUE"""),"Dominican Republic") -> Dominican Republic | M29: =IFERROR(__xludf.DUMMYFUNCTION("""COMPUTED_VALUE"""),"Cap Cana") -> Cap Cana | N29: =IFERROR(__xludf.DUMMYFUNCTION("""COMPUTED_VALUE"""),"Punta Cana") -> Punta Cana | O29: =IFERROR(__xludf.DUMMYFUNCTION("""COMPUTED_VALUE"""),TRUE) -> TRUE | P29: =IFERROR(__xludf.DUMMYFUNCTION("""COMPUTED_VALUE"""),0.011111111111111112) -> 0.011111111 | Q29: =IFERROR(__xludf.DUMMYFUNCTION("""COMPUTED_VALUE"""),"Hyatt") -> Hyatt | R29: =IFERROR(__xludf.DUMMYFUNCTION("""COMPUTED_VALUE"""),"Romantic, Ocean View") -> Romantic, Ocean View | S29: =IFERROR(__xludf.DUMMYFUNCTION("""COMPUTED_VALUE"""),"Beach, Great Food, Swim Out/Plunge Pool Rooms, Heated Pool, Gym, Yoga Classes, Swim Up Bar, Spa, Wifi (Free), Room Service, Nightclub, Evening Entertainment, Buffet") -> Beach, Great Food, Swim Out/Plunge Pool Rooms, Heated Pool, Gym, Yoga Classes, Swim Up Bar, Spa, Wifi (Free), Room Service, Nightclub, Evening Entertainment, Buffet | V29: =IFERROR(__xludf.DUMMYFUNCTION("""COMPUTED_VALUE"""),TRUE) -> TRUE | W29: =IFERROR(__xludf.DUMMYFUNCTION("""COMPUTED_VALUE"""),375.0) -> 375 | X29: =IFERROR(__xludf.DUMMYFUNCTION("""COMPUTED_VALUE"""),2019.0) -> 2019 | Z29: =IFERROR(__xludf.DUMMYFUNCTION("""COMPUTED_VALUE"""),8.0) -> 8
A30: =IFERROR(__xludf.DUMMYFUNCTION("""COMPUTED_VALUE"""),"Grand Velas Riviera Nayarit") -> Grand Velas Riviera Nayarit | B30: =IFERROR(__xludf.DUMMYFUNCTION("""COMPUTED_VALUE"""),96.0) -> 96 | C30: =IFERROR(__xludf.DUMMYFUNCTION("""COMPUTED_VALUE"""),"Family") -> Family | D30: =IFERROR(__xludf.DUMMYFUNCTION("""COMPUTED_VALUE"""),10003.98) -> 10003.98 | E30: =IFERROR(__xludf.DUMMYFUNCTION("""COMPUTED_VALUE"""),13815.995578601998) -> 13815.996 | F30: =IFERROR(__xludf.DUMMYFUNCTION("""COMPUTED_VALUE"""),1.6) -> 1.6 | G30: =IFERROR(__xludf.DUMMYFUNCTION("""COMPUTED_VALUE"""),5.0) -> 5 | H30: =IFERROR(__xludf.DUMMYFUNCTION("""COMPUTED_VALUE"""),9.0) -> 9 | J30: =IFERROR(__xludf.DUMMYFUNCTION("""COMPUTED_VALUE"""),5.0) -> 5 | L30: =IFERROR(__xludf.DUMMYFUNCTION("""COMPUTED_VALUE"""),"Mexico") -> Mexico | M30: =IFERROR(__xludf.DUMMYFUNCTION("""COMPUTED_VALUE"""),"Nuevo Vallarta") -> Nuevo Vallarta | N30: =IFERROR(__xludf.DUMMYFUNCTION("""COMPUTED_VALUE"""),"Ordaz") -> Ordaz | O30: =IFERROR(__xludf.DUMMYFUNCTION("""COMPUTED_VALUE"""),TRUE) -> TRUE | P30: =IFERROR(__xludf.DUMMYFUNCTION("""COMPUTED_VALUE"""),0.0125) -> 0.0125 | Q30: =IFERROR(__xludf.DUMMYFUNCTION("""COMPUTED_VALUE"""),"Velas Resorts") -> Velas Resorts | R30: =IFERROR(__xludf.DUMMYFUNCTION("""COMPUTED_VALUE"""),"Luxury, Family") -> Luxury, Family | S30: =IFERROR(__xludf.DUMMYFUNCTION("""COMPUTED_VALUE"""),"Beach, Great Food, Swim Out/Plunge Pool Rooms, Family Suite, 2 Bedroom Suites, Kids Club, Teen Club, Heated Pool, Gym, Bicycles Available, Wifi (Paid), Swim Up Bar, Diving, Nightclub, Spa, Babysitting, Room Service, Tennis, Evening Entertainment") -> Beach, Great Food, Swim Out/Plunge Pool Rooms, Family Suite, 2 Bedroom Suites, Kids Club, Teen Club, Heated Pool, Gym, Bicycles Available, Wifi (Paid), Swim Up Bar, Diving, Nightclub, Spa, Babysitting, Room Service, Tennis, Evening Entertainment | U30: =IFERROR(__xludf.DUMMYFUNCTION("""COMPUTED_VALUE"""),"1 King or 2 Queen") -> 1 King or 2 Queen | V30: =IFERROR(__xludf.DUMMYFUNCTION("""COMPUTED_VALUE"""),TRUE) -> TRUE | W30: =IFERROR(__xludf.DUMMYFUNCTION("""COMPUTED_VALUE"""),267.0) -> 267 | X30: =IFERROR(__xludf.DUMMYFUNCTION("""COMPUTED_VALUE"""),2002.0) -> 2002 | Y30: =IFERROR(__xludf.DUMMYFUNCTION("""COMPUTED_VALUE"""),2016.0) -> 2016 | Z30: =IFERROR(__xludf.DUMMYFUNCTION("""COMPUTED_VALUE"""),9.0) -> 9
A31: =IFERROR(__xludf.DUMMYFUNCTION("""COMPUTED_VALUE"""),"Grand Velas Riviera Maya") -> Grand Velas Riviera Maya | B31: =IFERROR(__xludf.DUMMYFUNCTION("""COMPUTED_VALUE"""),96.0) -> 96 | C31: =IFERROR(__xludf.DUMMYFUNCTION("""COMPUTED_VALUE"""),"Family") -> Family | D31: =IFERROR(__xludf.DUMMYFUNCTION("""COMPUTED_VALUE"""),11396.0) -> 11396 | E31: =IFERROR(__xludf.DUMMYFUNCTION("""COMPUTED_VALUE"""),15738.444660399999) -> 15738.445 | F31: =IFERROR(__xludf.DUMMYFUNCTION("""COMPUTED_VALUE"""),1.4) -> 1.4 | G31: =IFERROR(__xludf.DUMMYFUNCTION("""COMPUTED_VALUE"""),5.0) -> 5 | H31: =IFERROR(__xludf.DUMMYFUNCTION("""COMPUTED_VALUE"""),9.0) -> 9 | J31: =IFERROR(__xludf.DUMMYFUNCTION("""COMPUTED_VALUE"""),5.0) -> 5 | L31: =IFERROR(__xludf.DUMMYFUNCTION("""COMPUTED_VALUE"""),"Mexico") -> Mexico | M31: =IFERROR(__xludf.DUMMYFUNCTION("""COMPUTED_VALUE"""),"Playa del Carmen") -> Playa del Carmen | N31: =IFERROR(__xludf.DUMMYFUNCTION("""COMPUTED_VALUE"""),"Cancun") -> Cancun | O31: =IFERROR(__xludf.DUMMYFUNCTION("""COMPUTED_VALUE"""),TRUE) -> TRUE | P31: =IFERROR(__xludf.DUMMYFUNCTION("""COMPUTED_VALUE"""),0.027083333333333334) -> 0.027083333 | Q31: =IFERROR(__xludf.DUMMYFUNCTION("""COMPUTED_VALUE"""),"Velas Resorts") -> Velas Resorts | R31: =IFERROR(__xludf.DUMMYFUNCTION("""COMPUTED_VALUE"""),"Great View, Family") -> Great View, Family | S31: =IFERROR(__xludf.DUMMYFUNCTION("""COMPUTED_VALUE"""),"Beach, Great Food, Swim Out/Plunge Pool Rooms, Family Suite, 2 Bedroom Suites, Kids Club, Teen Club, Heated Pool, Gym, Diving, Spa, Wifi (Free), Babysitting, Swim Up Bar, Fishing, Room Service, Evening Entertainment") -> Beach, Great Food, Swim Out/Plunge Pool Rooms, Family Suite, 2 Bedroom Suites, Kids Club, Teen Club, Heated Pool, Gym, Diving, Spa, Wifi (Free), Babysitting, Swim Up Bar, Fishing, Room Service, Evening Entertainment | U31: =IFERROR(__xludf.DUMMYFUNCTION("""COMPUTED_VALUE"""),"1 King or 2 Queen") -> 1 King or 2 Queen | V31: =IFERROR(__xludf.DUMMYFUNCTION("""COMPUTED_VALUE"""),FALSE) -> FALSE | W31: =IFERROR(__xludf.DUMMYFUNCTION("""COMPUTED_VALUE"""),539.0) -> 539 | X31: =IFERROR(__xludf.DUMMYFUNCTION("""COMPUTED_VALUE"""),2008.0) -> 2008 | Y31: =IFERROR(__xludf.DUMMYFUNCTION("""COMPUTED_VALUE"""),2021.0) -> 2021 | Z31: =IFERROR(__xludf.DUMMYFUNCTION("""COMPUTED_VALUE"""),4.0) -> 4
A32: =IFERROR(__xludf.DUMMYFUNCTION("""COMPUTED_VALUE"""),"Spice Island Beach Resort") -> Spice Island Beach Resort | B32: =IFERROR(__xludf.DUMMYFUNCTION("""COMPUTED_VALUE"""),96.0) -> 96 | C32: =IFERROR(__xludf.DUMMYFUNCTION("""COMPUTED_VALUE"""),"Family") -> Family | D32: =IFERROR(__xludf.DUMMYFUNCTION("""COMPUTED_VALUE"""),18340.0) -> 18340 | E32: =IFERROR(__xludf.DUMMYFUNCTION("""COMPUTED_VALUE"""),25328.455165999996) -> 25328.455 | F32: =IFERROR(__xludf.DUMMYFUNCTION("""COMPUTED_VALUE"""),0.87) -> 0.87 | G32: =IFERROR(__xludf.DUMMYFUNCTION("""COMPUTED_VALUE"""),5.0) -> 5 | H32: =IFERROR(__xludf.DUMMYFUNCTION("""COMPUTED_VALUE"""),9.0) -> 9 | J32: =IFERROR(__xludf.DUMMYFUNCTION("""COMPUTED_VALUE"""),5.0) -> 5 | L32: =IFERROR(__xludf.DUMMYFUNCTION("""COMPUTED_VALUE"""),"Grenada") -> Grenada | M32: =IFERROR(__xludf.DUMMYFUNCTION("""COMPUTED_VALUE"""),"Grand Anse") -> Grand Anse | N32: =IFERROR(__xludf.DUMMYFUNCTION("""COMPUTED_VALUE"""),"Point Saline") -> Point Saline | O32: =IFERROR(__xludf.DUMMYFUNCTION("""COMPUTED_VALUE"""),FALSE) -> FALSE | P32: =IFERROR(__xludf.DUMMYFUNCTION("""COMPUTED_VALUE"""),0.006944444444444444) -> 0.0069444444 | R32: =IFERROR(__xludf.DUMMYFUNCTION("""COMPUTED_VALUE"""),"Family, Green") -> Family, Green | S32: =IFERROR(__xludf.DUMMYFUNCTION("""COMPUTED_VALUE"""),"Beach, Swim Out/Plunge Pool Rooms, Kids Club, Gym, Bicycles Available, Room Service, Tennis, Spa, Wifi (Free), Babysitting, Diving, Pets Allowed, Buffet") -> Beach, Swim Out/Plunge Pool Rooms, Kids Club, Gym, Bicycles Available, Room Service, Tennis, Spa, Wifi (Free), Babysitting, Diving, Pets Allowed, Buffet | U32: =IFERROR(__xludf.DUMMYFUNCTION("""COMPUTED_VALUE"""),"1 King or 2 Queen") -> 1 King or 2 Queen | V32: =IFERROR(__xludf.DUMMYFUNCTION("""COMPUTED_VALUE"""),FALSE) -> FALSE | W32: =IFERROR(__xludf.DUMMYFUNCTION("""COMPUTED_VALUE"""),64.0) -> 64 | X32: =IFERROR(__xludf.DUMMYFUNCTION("""COMPUTED_VALUE"""),1961.0) -> 1961 | Y32: =IFERROR(__xludf.DUMMYFUNCTION("""COMPUTED_VALUE"""),2023.0) -> 2023 | Z32: =IFERROR(__xludf.DUMMYFUNCTION("""COMPUTED_VALUE"""),2.0) -> 2
