Workbook
Name _123: Input!$A$16:$G$21
Name _2: Input!$A$16:$G$21
Name listings_2011_2_17_10_4_33: Input!$A$33:$C$46
Name T_A_E_E: Input!$A$12:$E$18
Name test_1: Input!#REF!

Sheet Input
A1: Input Date Sheet | H1: Additional MLS Set Up
H2: We import Technical and Neighborhood from the mls. Our mls its called column manager its were you can pick and choose which fields are show. Then we export into a text document and import into this sheet
A3: Prepared for | B3: Edward and Jennifer Lopes
A4: Property Address | B4: 2909 Greenfield Road
A5: City, State Zip | B5: Glenshaw PA 15116
A6: Team | B6: Matthew McKenna | H6: Technical Analysis
A7: Date | B7: March 26th 2014 | H7: Address | I7: DOM | J7: Assessment | K7: List price | L7: Sold price
H8: Neighborhood
A9: Equity Evaluation | H9: Address | I9: Sold Date | J9: Sold Price
H10: *Note Neighhood the most recent sold date comes first
A11: Technical Analysis
A12: 197 Washington Street | B12: 257 | C12: 104400 | D12: 139900 | E12: 134000 | G12: Technical Analysis - Click on the Red cell - Click Data - Click Import External Data - Click Import Data - Navagate to where you saved the MLS data Click Open - Click Next - Check Mark Comma - Click Finished
A13: 112 Lammert | B13: 74 | C13: 137800 | D13: 168000 | E13: 168000
A14: 1509 CLINTON ROAD | B14: 237 | C14: 98100 | D14: 165000 | E14: 165000
A15: 203 Woodland Ave | B15: 105 | C15: 96900 | D15: 159000 | E15: 156250
A16: 235 Soose Road | B16: 243 | C16: 100800 | D16: 159900 | E16: 159900
A17: 1903 SHALER DRIVE | B17: 26 | C17: 107900 | D17: 149900 | E17: 153000
A18: 178 Alma | B18: 52 | C18: 122100 | D18: 189900 | E18: 185000
A19: Current Assessment: | B19: 120600
A21: Internet Estimates
A22: Address | B22: Eppraisal | D22: Zillow
A23: =B4 -> 2909 Greenfield Road | B23: 184412 | D23: 136100 | G23: Yellow is Subject property
A24: =A12 -> 197 Washington Street | B24: 102472 | D24: 134800
A25: =A13 -> 112 Lammert | B25: 194891 | D25: 170100
A26: =A14 -> 1509 CLINTON ROAD | B26: 116093 | D26: 146200
A27: =A15 -> 203 Woodland Ave | B27: 123951 | D27: 146900
A28: =A16 -> 235 Soose Road | B28: 111015 | D28: 143700
A29: =A17 -> 1903 SHALER DRIVE | B29: 112682 | D29: 146700
A30: =A18 -> 178 Alma | B30: 118864 | D30: 160100
A32: Neighborhood | D32: Don't Touch | G32: This Year | H32: 2012
A33: 178 Alma | B33: 39421 | C33: 157500 | D33: =YEAR(B33) -> 2007 | E33: =(C33-C34)/(D33-D34) -> 6875 | F33: =((C33-C34)/(D33-D34))/C33 -> 0.043650794 | G33: Purchase Year | H33: 2007
A34: 178 Alma | B34: 40753 | C34: 185000 | D34: =YEAR(B34) -> 2011 | G34: Purchase Price | H34: 124900
A35: 113 Cherrywood Drive | B35: 37704 | C35: 142000 | D35: =YEAR(B36) -> 2006 | E35: =(C35-C36)/(D35-D36) -> 2000 | F35: =((C35-C36)/(D35-D36))/C35 -> 0.014084507
A36: 113 Cherrywood | B36: 38744 | C36: 136000 | D36: =YEAR(B35) -> 2003
A37: 36 Colony Oaks Drive | B37: 38721 | C37: 169900 | D37: =YEAR(B37) -> 2006 | E37: =(C37-C38)/(D37-D38) -> 4050 | F37: =((C37-C38)/(D37-D38))/C37 -> 0.023837552
A38: 36 Colony Oaks Drive | B38: 39717 | C38: 178000 | D38: =YEAR(B38) -> 2008
A39: 452 D Street | B39: 37680 | C39: 154000 | D39: =YEAR(B39) -> 2003 | E39: =(C39-C40)/(D39-D40) -> 5428.5714 | F39: =((C39-C40)/(D39-D40))/C39 -> 0.035250464
A40: 452 D Street | B40: 40498 | C40: 192000 | D40: =YEAR(B40) -> 2010
A41: 110 Franklin Avenue | B41: 40065 | C41: 145700 | D41: =YEAR(B41) -> 2009 | E41: =(C41-C42)/(D41-D42) -> 3425 | F41: =((C41-C42)/(D41-D42))/C41 -> 0.023507207
A42: 110 Franklin Avenue | B42: 38487 | C42: 132000 | D42: =YEAR(B42) -> 2005
...

Sheet EqEval
B5: =Input!$A9 -> Equity Evaluation
B10: Prepared For:
B13: =Input!$B3 -> Edward and Jennifer Lopes
B19: =Input!$B4 -> 2909 Greenfield Road
B22: =Input!$B5 -> Glenshaw PA 15116
B61: Evaluation Range: $160,000-$165,000
B66: Target Price: $165,000
B71: =Input!$B6&", "&Input!$B7 -> Matthew McKenna, March 26th 2014

Sheet PrEval
B5: =Input!$A9 -> Equity Evaluation
B10: Prepared For:
B13: =Input!$B3 -> Edward and Jennifer Lopes
B19: =Input!$B4 -> 2909 Greenfield Road
B22: =Input!$B5 -> Glenshaw PA 15116
B61: Price: $165000
B71: =Input!$B6&", "&Input!$B7 -> Matthew McKenna, March 26th 2014

Sheet Overview1
C4: =Input!$A9&" Overview" -> Equity Evaluation Overview
B8: Purpose:
B10: =Input!$A57& Input!$A9& Input!$A58& Input!$A9& Input!$A59 -> I prepare a customized Equity Evaluation to establish a market-competitive selling price for each of our listings. My evaluation may include many separate analyses to arrive at a recommended listing price competitive with current market prices in a given area. It acknowledges a home's distinctive features that should attract interested buyers, and increases the probability that I will sell homes at the correct price. I draw on data from multiple sources to conduct each of the analyses listed and described below. Many factors influence my decisions regarding which analyses will be weighted most heavily in setting the price for my homes. I welcome your questions, and will be pleased to explain this Equity Evaluation in more detail.
B20: 1. Comparable Market Analysis (CMA)
B21: 2. Neighborhood Appreciation
B22: 3. Technical Analysis
B23: 4. Internet Estimates
B25: Description:
B27: =Input!$A60& Input!$A9& Input!$A61 -> Below are brief descriptions of each of the methods of analysis we use in preparing Equity Evaluations. More thorough descriptions can be found on cover pages that introduce each section with an explanation of the research process, the data selection criteria that were used and why they were used, and the weight we typically place on the results of the research in arriving at a home's target price.
B33: =IF(B20=" "," ",IF(B20="1. Comparable Market Analysis (CMA)",B20&":",IF(B20="1. Neighborhood Appreciation",B20&":",IF(B20="1. Technical Analysis",B20&":",IF(B20="1. Internet Estimates",B20&":"," "))))) -> 1. Comparable Market Analysis (CMA):
B35: =IF(B33="1. Comparable Market Analysis (CMA):", Input!B67, IF(B33="1. Neighborhood Appreciation:", Input!B68, IF(B33="1. Technical Analysis:", Input!B69, IF(B33="1. Internet Estimates:", Input!B70," ")))) -> The CMA evaluates homes in an area that have comparable characteristics to the subject property. I typically research homes by school district or area, and look at the number of bedrooms and bathrooms and countless other characteristics that determine a home's value, such as a finished lower level or an attached garage. My analysis includes homes that are Active, Contingent, Under Agreement, and -- most importantly -- ones that have Sold to determine the nature of the competitive market in the area and the types of homes that are selling. Of all our methods of analysis, the CMA carries the most weight in determining the correct listing price.
B43: =IF(B21=" "," ",IF(B21="2. Comparable Market Analysis (CMA)",B21&":",IF(B21="2. Neighborhood Appreciation",B21&":",IF(B21="2. Technical Analysis",B21&":",IF(B21="2. Internet Estimates",B21&":"," "))))) -> 2. Neighborhood Appreciation:
B45: =IF(B43="2. Comparable Market Analysis (CMA):", Input!B67, IF(B43="2. Neighborhood Appreciation:", Input!B68, IF(B43="2. Technical Analysis:", Input!B69, IF(B43="2. Internet Estimates:", Input!B68," ")))) -> This method assesses multiple past sales in the subject property's subdivision, adjoining streets, or in a several-block radius to determine the average annual appreciation or depreciation in property values in the area. Appreciation or depreciation is defined as a change in value over time, and can be due to a number of factors such as new roadways, new access to shopping centers, or a change in the average price of homes being built in the area. To arrive at an annual percentage increase or decrease, I look at several homes that have sold at least twice in the past ten years. I compare the two sale prices and sale dates to arrive at an estimate of the change in each home's market value. I then apply the average change in value for all the homes sampled to estimate a change in value for the subject property since the date it was purchased.
B67: =Input!$B6&", "&Input!$B7 -> Matthew McKenna, March 26th 2014

Sheet Overview2
C4: =Input!$A9&" Overview" -> Equity Evaluation Overview
B8: Description:
B11: =IF(Overview1!B22=" "," ",IF(Overview1!B22="3. Comparable Market Analysis (CMA)",Overview1!B22&":",IF(Overview1!B22="3. Neighborhood Appreciation",Overview1!B22&":",IF(Overview1!B22="3. Technical Analysis",Overview1!B22&":",IF(Overview1!B22="3. Internet Estimates",Overview1!B22&":"," "))))) -> 3. Technical Analysis:
B13: =IF(B11="3. Comparable Market Analysis (CMA):", Input!B67, IF(B11="3. Neighborhood Appreciation:", Input!B68, IF(B11="3. Technical Analysis:", Input!B69, IF(B11="3. Internet Estimates:", Input!B70," ")))) -> It is a common mistake for home owners or prospective buyers to assume that the assessed value of a home reflects its true value or the price at which it would sell. Assessed values (sometimes referred to as Market Values) are used primarily for determining property taxes and are typically outdated. For example, the assessed values for homes in Allegheny County are from assessments conducted in 2001, and may not be reflective of current home values. Even if outdated, assessed values can be useful in calculating the current value of a home. Since assessments are typically conducted for all the homes in a given area during the same year, the assessed value for one home can be used for comparison to another home. My research methodology identifies homes that sold within an area within the past year and compares the prices at which they sold to their assessed values. For each home, we calculate a percentage ratio of the sold price to the assessed value. Then I apply the high, low and average percentage ratios from our sample of homes to the subject property's current assessed value to calculate a listing price and a price range.
B26: =IF(Overview1!B23=" "," ",IF(Overview1!B23="4. Comparable Market Analysis (CMA)",Overview1!B23&":",IF(Overview1!B23="4. Neighborhood Appreciation",Overview1!B23&":",IF(Overview1!B23="4. Technical Analysis",Overview1!B22&":",IF(Overview1!B23="4. Internet Estimates",Overview1!B23&":"," "))))) -> 4. Internet Estimates:
B28: =IF(B26="4. Comparable Market Analysis (CMA):", Input!B67, IF(B26="4. Neighborhood Appreciation:", Input!B68, IF(B26="4. Technical Analysis:", Input!B69, IF(B26="4. Internet Estimates:", Input!B70," ")))) -> All professional real estate agents in our area have access to the West Penn Multi List (MLS), which is an expansive database of all homes that have been listed for sale or have sold within the past fifteen years. This is the primary tool used by agents to research the current and past real estate market. Only licensed agents can access this service, therefore many potential home buyers or sellers who wish to research homes themselves use free internet services such as Epprasial or Zillow. Their estimates of home values draw from different pools of information that include assessed values, past sales, current sales, and active listings. While they can be a useful source of information, they rely on sources of data and research methodologies that vary from one site to another and that may compromise the quality of information they present. This section has the least amount of bearing on determining the price of a home and is simply used as another reference.
B48: If you have any further questions regarding this information, please feel free to contact me at 724.933.8500 ext. 8663.
B66: ="This "&Input!$A9&" has been prepared for the exclusive use of The Matthew McKenna Home Selling System and its represented clients. No representations are made regarding the accuracy of the analyses and the recommendations made herein." -> This Equity Evaluation has been prepared for the exclusive use of The Matthew McKenna Home Selling System and its represented clients. _x000D_No representations are made regarding the accuracy of the analyses and the recommendations made herein.
B69: =Input!$B6&", "&Input!$B7 -> Matthew McKenna, March 26th 2014

Sheet Comparable1
C4: =Input!$A9 -> Equity Evaluation
C8: Comparable Market Analysis (CMA)
B11: Definition:
B13: The CMA is an analysis of other homes in the area that have comparable characteristics to the subject property.
B15: Criteria:
B17: For our CMA's, we generally use the following criteria:
B19: 1. Active, Contingent, Under Agreement, Sold Homes (ASCU)
B20: 2. School District
B21: 3. Number of Bedrooms
B22: 4. Number of Bathrooms
B23: 5. Homes that have been on the market in the past year (12 months)
B25: I apply the criteria listed above to produce a selection of homes that compare very closely to the subject property. On the following pages you will find a summary of the important results of our research, an MLS page for each of the comparable homes selected for our analysis, and statistical data categorized by the Active, Contingent, Under Agreement, and Sold statuses.
B31: Process:
B33: First I identify the geographical area from which to select comparable homes. Depending on the market in the area, I may either choose to limit the geography to an area closer to the subject property because there is so much activity, or broaden the area because of a lack of activity. Once the area is determined, I search for comparable homes based on a few key criteria such as the number of bedrooms and bathrooms.
B39: I look first at homes that are Active or Contingent, since they best represent the competition our property faces. Once I have a good understanding of the competition, I look at homes that have been Sold or are Under Agreement. These homes provide the best evidence of what homes are selling for in the area, and weigh much heavier than the active homes in determining a list price.
B45: =Input!$B4&" Analysis:" -> 2909 Greenfield Road Analysis:
B57: Research Results:
B68: =Input!$B6&", "&Input!$B7 -> Matthew McKenna, March 26th 2014

Sheet Comparable
B4: =Input!$A9 -> Equity Evaluation
B9: Prepared For:
B11: =Input!$B3 -> Edward and Jennifer Lopes
B14: =Input!$B4&", "&Input!$B5 -> 2909 Greenfield Road, Glenshaw PA 15116
B19: Comparable Market Analysis
B25: Criteria Used for Report: | F25: ASCU, 3 Bedrooms, 2 Bathrooms, Any Price, Past Year Sales
B28: Average Days on Market: | I28: 142
B31: Average List Price: | I31: 140535
B34: Average Sold Price: | I34: 143218
B37: Average Asked to Sold Ratio: | I37: 0.96
B40: Units Sold in Last Year: | I40: 35
B43: Units on the Market: | I43: 6
B46: Absorption Rate* (Months): | I46: =Input!$A52 -> 2.0571429
B51: =Input!$B4&" Price Range:" -> 2909 Greenfield Road Price Range: | I51: $160,000 - $165,000
B55: Research Results:
B57: =Comparable1!$B$59 -> _x000D_
B67: * Absorption Rate: at the current market rate of sales, the average number of months it would take for all active listing inventory to be sold.
B70: =Input!$B6&", "&Input!$B7 -> Matthew McKenna, March 26th 2014

Sheet Neighborhood1
C3: =Input!$A9 -> Equity Evaluation
C7: Neighborhood Appreciation/Depreciation Analysis
B10: Definition:
B12: The Neighborhood Appreciation/Depreciation Analysis assesses multiple past sales in a subdivision, on adjoining streets, or in a several-block radius of the subject property to determine the average annual appreciation or depreciation in property values in the area.
B17: Criteria:
B19: For this research, I look at homes in the neighborhood that have sold at least two times within the past twelve years. I try to find at least three homes for comparison.
B23: Process:
B25: Appreciation or depreciation is defined as a change in value over time, and can be due to a number of factors such as new roadways, new access to shopping centers, or a change in the average price of homes being built in the area. To arrive at an annual percentage increase or decrease, I look at several homes that have sold at least twice in the past ten years. I compare the two sale prices and sale dates to arrive at an estimate of the change in each home's market value. I then apply the average annual change in value for all the homes sampled to estimate a change in value for the subject property since the date it was purchased.
B33: Research Results:
B69: =Input!$B6&", "&Input!$B7 -> Matthew McKenna, March 26th 2014

Sheet Neighborhood
B5: =Input!$A9 -> Equity Evaluation
B9: Prepared For:
B11: =Input!$B3 -> Edward and Jennifer Lopes
B14: =Input!$B4&", "&Input!$B5 -> 2909 Greenfield Road, Glenshaw PA 15116
B19: Neighborhood Appreciation
B25: Comparable Address | H25: +/- | K25: Yearly Change $ | P25: Yearly Change %
B28: =Input!$A33 -> 178 Alma | H28: + | K28: =Input!$E33 -> 6875 | P28: =Input!$F33 -> 0.043650794
B31: =Input!$A35 -> 113 Cherrywood Drive | H31: + | K31: =Input!$E35 -> 2000 | P31: =Input!$F35 -> 0.014084507
B34: =Input!$A37 -> 36 Colony Oaks Drive | H34: + | K34: =Input!$E37 -> 4050 | P34: =Input!$F37 -> 0.023837552
B37: =Input!$A39 -> 452 D Street | H37: + | K37: =Input!$E39 -> 5428.5714 | P37: =Input!$F39 -> 0.035250464
B40: =Input!$A41 -> 110 Franklin Avenue | H40: + | K40: =Input!$E41 -> 3425 | P40: =Input!$F41 -> 0.023507207
B43: =Input!$A43 -> 6 Barrington Dr | H43: + | K43: =Input!$E43 -> 9875 | P43: =Input!$F43 -> 0.073148148
B46: =Input!$A45 -> 404 S HIGHLANDER HT | H46: + | K46: =Input!$E45 -> 3500 | P46: =Input!$F45 -> 0.025547445
B51: Average: | H51: + | K51: =AVERAGE(K28:K46) -> 5021.9388 | P51: =AVERAGE(P28:P46) -> 0.034146588
B56: Address | I56: Year Purchased | O56: Purchase Price
B60: =Input!$B4 -> 2909 Greenfield Road | I60: =Input!$H33 -> 2007 | O60: =Input!$H34 -> 124900
B66: Estimated Current Value | I66: =O60*P51*(Input!$H32-Input!$H33)+O60 -> 146224.54
B70: =Input!$B6&", "&Input!$B7 -> Matthew McKenna, March 26th 2014

Sheet Technical1
C3: =Input!$A9 -> Equity Evaluation
C7: Technical Analysis
B11: Definition:
B13: The Technical Analysis calculates a percentage ratio of the assessed values of a sample of homes to the prices at which they sold, and applies that ratio to the subject home's assessed value to estimate a sale price for the home.
B17: Criteria:
B19: I select a sample of comparable homes in the area of the subject property that have sold within the past year.
B21: Process:
B23: This analysis rests on the assumption that there is a relationship between the assessed value of a home and the price at which it sells. Assessed values (sometimes referred to as Market Values) are used primarily for determining property taxes and are usually outdated. They can serve a useful purpose, however. Since assessments are typically conducted for all the homes in a given area during the same year, the assessed value for one home can be used for comparison to another home. My research methodology identifies homes that sold in the area within the past year and compares the prices at which they sold to their assessed values. To begin the analysis, the assessed value, list price (original asking price), and final sale price for each of the comparable homes selected are entered into a table. I also include for your reference the number of days each home was on the market (DOM), which is the lapsed time between the date the home was listed and the date on which it went under agreement. A percentage ratio is determined by dividing each home's sale price by its assessed value. Then I use the low, median, average, and high percentages to "back into" an estimated sale price and price range for the subject property based on its current assessed value. The table on the following page summarizes our research and calculations.
B41: Research Results:
B68: =Input!$B6&", "&Input!$B7 -> Matthew McKenna, March 26th 2014

Sheet Technical
B5: =Input!$A9 -> Equity Evaluation
C9: Prepared For:
B11: =Input!$B3 -> Edward and Jennifer Lopes
B15: =Input!$B4&", "&Input!$B5 -> 2909 Greenfield Road, Glenshaw PA 15116
B19: Technical Analysis
B24: Address | F24: DOM* | G24: Current Assessment | K24: List Price | O24: Sold Price | R24: SP/CA**
B27: =Input!$A12 -> 197 Washington Street | F27: =Input!$B12 -> 257 | G27: =Input!$C12 -> 104400 | K27: =Input!$D12 -> 139900 | O27: =Input!$E12 -> 134000 | R27: =O27/G27 -> 1.2835249
B30: =Input!$A13 -> 112 Lammert | F30: =Input!$B13 -> 74 | G30: =Input!$C13 -> 137800 | K30: =Input!$D13 -> 168000 | O30: =Input!$E13 -> 168000 | R30: =O30/G30 -> 1.2191582
B33: =Input!$A14 -> 1509 CLINTON ROAD | F33: =Input!$B14 -> 237 | G33: =Input!$C14 -> 98100 | K33: =Input!$D14 -> 165000 | O33: =Input!$E14 -> 165000 | R33: =O33/G33 -> 1.6819572
B36: =Input!$A15 -> 203 Woodland Ave | F36: =Input!$B15 -> 105 | G36: =Input!$C15 -> 96900 | K36: =Input!$D15 -> 159000 | O36: =Input!$E15 -> 156250 | R36: =O36/G36 -> 1.6124871
B39: =Input!$A16 -> 235 Soose Road | F39: =Input!$B16 -> 243 | G39: =Input!$C16 -> 100800 | K39: =Input!$D16 -> 159900 | O39: =Input!$E16 -> 159900 | R39: =O39/G39 -> 1.5863095
B42: =Input!$A17 -> 1903 SHALER DRIVE | F42: =Input!$B17 -> 26 | G42: =Input!$C17 -> 107900 | K42: =Input!$D17 -> 149900 | O42: =Input!$E17 -> 153000 | R42: =O42/G42 -> 1.4179796
B45: =Input!$A18 -> 178 Alma | F45: =Input!$B18 -> 52 | G45: =Input!$C18 -> 122100 | K45: =Input!$D18 -> 189900 | O45: =Input!$E18 -> 185000 | R45: =O45/G45 -> 1.5151515
F50: Current Assessment
B53: =Input!$B4 -> 2909 Greenfield Road | F53: =Input!$B19 -> 120600 | J53: Low | M53: = | N53: =MIN(R27:R45) -> 1.2191582 | Q53: =F53*N53 -> 147030.48
B56: Average Days On Market | F56: =AVERAGE(F27:F45) -> 142 | J56: Average | M56: = | N56: =AVERAGE(R27:R45) -> 1.4737954 | Q56: =F53*N56 -> 177739.73
J59: High | M59: = | N59: =MAX(R27:R45) -> 1.6819572 | Q59: =F53*N59 -> 202844.04
J62: Median | M62: = | N62: =MEDIAN(R27:R45) -> 1.5151515 | Q62: =F53*N62 -> 182727.27
B66: * DOM - Means "days on market", or how long the home has been listed for sale
B67: ** SP/CA - Sales Price/Current Assessment
B69: =Input!$B6&", "&Input!$B7 -> Matthew McKenna, March 26th 2014

Sheet Internet1
C3: =Input!$A9 -> Equity Evaluation
C7: Internet Estimates
B12: Definition:
B14: This analysis utilizes free internet sites that are available to the public.
B16: Criteria:
B18: I utilize two of the most popular internet sites for researching real estate: Eppraisal and Zillow.
B20: Process:
B22: I have evaluated numerous real estate internet sites to select those that, in our estimate, provide the most credible and reliable information. Each site treats its research methodologies and data sources as proprietary, so we are limited in our ability to assess the quality of their research and analyses. However, when I compare the sites to one another or compare their recommended listing prices to our own and to actual sale prices, we see differences that are significant enough to cause us concern. Many buyers and sellers who do their own research utilize these free internet sites, so I feel it is in our best interest to know what they recommend as a target price for each of my listings. On the following page we provide internet estimates from each of the following two sites:
B32: Eppraisal:
B34: Is often used by mortgage companies to estimate the value of a home. Perhaps the most reliable internet website, it bases its recommendations on past sales, active homes, and the assessed value of homes in the area.
B38: Zillow:
B40: Uses the county's assessed value as its primary source of information to determine the value of a home.
B42: Research Results:
B69: =Input!$B6&", "&Input!$B7 -> Matthew McKenna, March 26th 2014

Sheet Internet
C5: =Input!$A9 -> Equity Evaluation
C9: Prepared For:
C11: =Input!$B3 -> Edward and Jennifer Lopes
C14: =Input!$B4&", "&Input!$B5 -> 2909 Greenfield Road, Glenshaw PA 15116
C17: Internet Estimates
C22: =Input!$B4&":" -> 2909 Greenfield Road: | L22: Epprasial: | Q22: =Input!$B23 -> 184412
L25: Zillow: | Q25: =Input!$D23 -> 136100
E31: =Input!$A12&":" -> 197 Washington Street: | L31: Sale Price: | P31: =Input!$E12 -> 134000
L34: Eppraisal: | P34: =Input!$B24 -> 102472
L37: Zillow: | P37: =Input!$D24 -> 134800
E44: =Input!$A13&":" -> 112 Lammert: | L44: Sale Price: | P44: =Input!$E13 -> 168000
L47: Eppraisal: | P47: =Input!$B25 -> 194891
L50: Zillow: | P50: =Input!$D25 -> 170100
E57: =Input!$A14&":" -> 1509 CLINTON ROAD: | L57: Sale Price: | P57: =Input!$E14 -> 165000
L60: Eppraisal: | P60: =Input!$B26 -> 116093
L63: Zillow: | P63: =Input!$D26 -> 146200
C70: =Input!$B6&", "&Input!$B7 -> Matthew McKenna, March 26th 2014

Sheet Internet2
C5: =Input!$A9 -> Equity Evaluation
C9: Internet Estimates
E14: =Input!$A15&":" -> 203 Woodland Ave: | L14: Sale Price: | P14: =Input!$E15 -> 156250
L17: Eppraisal: | P17: =Input!$B27 -> 123951
L20: Zillow: | P20: =Input!$D27 -> 146900
E26: =Input!$A16&":" -> 235 Soose Road: | L26: Sale Price: | P26: =Input!$E16 -> 159900
L29: Eppraisal: | P29: =Input!$B28 -> 111015
L32: Zillow: | P32: =Input!$D28 -> 143700
E38: =Input!$A17&":" -> 1903 SHALER DRIVE: | L38: Sale Price: | P38: =Input!$E17 -> 153000
L41: Eppraisal: | P41: =Input!$B29 -> 112682
L44: Zillow: | P44: =Input!$D29 -> 146700
E50: =Input!$A18&":" -> 178 Alma: | L50: Sale Price: | P50: =Input!$E18 -> 185000
L53: Eppraisal: | P53: =Input!$B30 -> 118864
L56: Zillow: | P56: =Input!$D30 -> 160100
E61: Averages: | J61: Sale Price: | O61: =AVERAGE(Internet!P31,Internet!P44,Internet!P57,Internet2!P14,Internet2!P26,Internet2!P38,Internet2!P50) -> 160164.29
J64: Epprasial: | O64: =AVERAGE(Internet!P34,Internet!P47,Internet!P60,P17,P29,P41,P53) -> 125709.71
J67: Zillow: | O67: =AVERAGE(Internet!P37,Internet!P50,Internet!P63,Internet2!P20,Internet2!P32,Internet2!P44,Internet2!P56) -> 149785.71
C70: =Input!$B6&", "&Input!$B7 -> Matthew McKenna, March 26th 2014

Sheet Equity Evaluation
B3: =Input!$A9 -> Equity Evaluation
B10: Summary of Research Results
B15: =Input!$B4&", "&Input!$B5 -> 2909 Greenfield Road, Glenshaw PA 15116
C21: 1. Comparable Market Analysis | K21: =Comparable!$I51 -> $160,000 - $165,000
C27: 2. Neighborhood Appreciation/Depreciation | L27: =Neighborhood!$I66 -> 146224.54
C33: 3. Technical Analysis | L33: =Technical!$Q56 -> 177739.73
C39: 4. Internet Estimates
F42: Eppraisal.com | L42: =Internet2!$O64 -> 125709.71
F45: Zillow.com | L45: =Internet2!$O67 -> 149785.71
G56: =EqEval!$B61 -> Evaluation Range: $160,000-$165,000
G62: =EqEval!$B66 -> Target Price: $165,000
B68: =Input!$B6&", "&Input!$B7 -> Matthew McKenna, March 26th 2014

Sheet Price Evaluation
B3: =Input!$A9 -> Equity Evaluation
B10: Summary of Research Results
B15: =Input!$B4&", "&Input!$B5 -> 2909 Greenfield Road, Glenshaw PA 15116
C21: 1. Comparable Market Analysis | K21: =Comparable!$I51 -> $160,000 - $165,000
C27: 2. Neighborhood Appreciation/Depreciation | L27: =Neighborhood!$I66 -> 146224.54
C33: 3. Technical Analysis | L33: =Technical!$Q56 -> 177739.73
C39: 4. Internet Estimates
F42: Eppraisal.com | L42: =Internet2!$O64 -> 125709.71
F45: Zillow.com | L45: =Internet2!$O67 -> 149785.71
G58: =PrEval!$B61 -> Price: $165000
B71: =Input!$B6&", "&Input!$B7 -> Matthew McKenna, March 26th 2014
